Workbook
Name _Toc226895311_10: "$#ССЫЛ!.$#ССЫЛ!$#ССЫЛ!"
Name Excel_BuiltIn_Print_Titles_29: #REF!
Name Excel_BuiltIn_Print_Titles_29: #REF!
Name k: #N/A
Name m: #N/A
Name n: #N/A
Name а: #REF!
Name а: #REF!
Name аа: #REF!
Name аа: #REF!
Name астана: #REF!
Name астана: #REF!
Name ВидПредмета: #NAME?
Name вода: #REF!
Name вода: #REF!
Name г: #REF!
Name г: #REF!
Name Год: #NAME?
Name Интеллектуальная_школа_Первого_Президента_физико_математического_направления_в_городе_Астана: #REF!
Name Интеллектуальная_школа_Первого_Президента_физико_математического_направления_в_городе_Астана: #REF!
Name кк: #REF!
Name кк: #REF!
Name л: #REF!
Name л: #REF!
Name ллл: #REF!
Name ллл: #REF!
Name март: #REF!
Name март: #REF!
Name пнпп: #REF!
Name пнпп: #REF!
Name пп: #REF!
Name пп: #REF!
Name ппре: #REF!
Name ппре: #REF!
Name прпам: #REF!
Name прпам: #REF!
Name Способ: #NAME?
Name Тарификация: #REF!
Name Тарификация: #REF!

Sheet Свод 
B2: Сводный расчет расходов на 2026-2028 годы
B5: По бюджетной программе 004 «Обеспечение доступности качественного школьного образования»
B6: по 100 подпрограмме «Обучение и воспитание детей в республиканских организациях образования»
B7: Контингент учащихся 1186
A9: № | B9: Наименование расходов | C9: 2026г | D9: 2027г | E9: 2028г
A10: 1 | B10: Оплата труда | C10: 1 | D10: 1 | E10: 1
A11: =A10+1 -> 2 | B11: Компенсационные выплаты | C11: 1 | D11: 1 | E11: 1
A12: =A11+1 -> 3 | B12: Социальный налог 6% | C12: 1 | D12: 1 | E12: 1
A13: =A12+1 -> 4 | B13: Социальные отчисления 5% | C13: 1 | D13: 1 | E13: 1
A14: =A13+1 -> 5 | B14: Обязательное социальное медицинское страхование 3% | C14: 1 | D14: 1 | E14: 1
A15: =A14+1 -> 6 | B15: Обязательные пенсионные взносы 3,5%-4,5% | C15: 1 | D15: 1 | E15: 1
A16: =A15+1 -> 7 | B16: Приобретение продуктов питания (питьевая вода) | C16: 1 | D16: 1 | E16: 1
A17: =A16+1 -> 8 | B17: Приобретение медикаментов и прочих средств медицинского назначения | C17: 1 | D17: 1 | E17: 1
A18: =A17+1 -> 9 | B18: Приобретение горюче-смазочных материалов | C18: 1 | D18: 1 | E18: 1
A19: =A18+1 -> 10 | B19: Приобретение прочих запасов | C19: 1 | D19: 1 | E19: 1
A20: =A19+1 -> 11 | B20: Коммунальные услуги | C20: 1 | D20: 1 | E20: 1
A21: =A20+1 -> 12 | B21: Услуги связи и интернет | C21: 1 | D21: 1 | E21: 1
A22: =A21+1 -> 13 | B22: Прочие услуги и работы | C22: 1 | D22: 1 | E22: 1
... A25: =A24+1 -> 16 | B25: Прочие текущие затраты | C25: 1 | D25: 1 | E25: 1
B26: Итого | C26: =SUM(C10:C25) -> 16 | D26: =SUM(D10:D25) -> 16 | E26: =SUM(E10:E25) -> 16
B39: Председатель Правления НАО "РФМШ" | C39: Бекахметов Г.К.
B41: Заместитель ПП по ФЭВ НАО "РФМШ" | C41: Рахимжанова А.С.
B43: Гл.бухгалтер НАО "РФМШ" | C43: Алпыспаева Г.Ж.
B45: Экономист НАО "РФМШ" | C45: Машекова Ф.А

Sheet ДОХОДНАЯ ЧАСТЬ РБ
C2: Свод дополнительной доходной части филиала НАО "РФМШ" в городе Алматы на 01 января 2026 года
B4: 1. | C4: Доходная часть филиала НАО "РФМШ" в городе Алматы за счет средств республиканского бюджета государственный образовательный грант на 2026 год
B5: № п/п | C5: Наименование филиала НАО "РФМШ" | D5: Классы | E5: Контингент учащихся | F5: План поступлений по месяцам на 2026 год согласно бюджетной заявки МП РК (в тенге) | R5: Стоимость на одного в тенге | T5: Всего сумма поступлений за счет РБ на 2026 год (тенге)
F6: январь | G6: февраль | H6: март | I6: апрель | J6: май 1,3 | K6: июнь 1,4 | L6: июль 0,7 | M6: август 0,6 | N6: сентябрь | O6: октябрь | P6: ноябрь | Q6: декабрь | R6: в месяц | S6: в год
B7: 1 | C7: Филиал НАО "РФМШ" в г Алматы | D7: с 7 по11 кл | E7: 1186 | F7: 1 | G7: 1 | H7: 1 | I7: 1 | J7: 1 | K7: 1 | L7: 1 | M7: 1 | N7: 1 | O7: 1 | P7: 1 | Q7: 1 | R7: 1 | S7: 1 | T7: 1
C8: Итого | F8: =F7 -> 1 | G8: =G7 -> 1 | H8: =H7 -> 1 | I8: =I7 -> 1 | J8: =J7 -> 1 | K8: =K7 -> 1 | L8: =L7 -> 1 | M8: =M7 -> 1 | ... T8: =T7 -> 1

Sheet Сводная общая 2026г.
C3: Сводный расчет расходов на 2026 год
C4: ФНАО «Республиканская физико-математическая школа» в г.Алматы
C5: по бюджетной программе 004 «Обеспечение доступности качественного школьного образования»
C6: по 100 подпрограмме «Обучение и воспитание детей в республиканских организациях образования»
C8: 1. Фонд Оплаты Труда | H8: =H10+H11+H12+H13+H14+H15+H16 -> 12
B9: № п.п | C9: Наименование расходов | H9: Сумма затрат в тенге в рамках лимита
B10: 1 | C10: Штатное расписание | H10: ='СВОД ФЗП'!F12 -> 1
B11: =B10+1 -> 2 | C11: Оплата труда по тарификации учителей | H11: ='СВОД ФЗП'!F13 -> 1
B12: =B11+1 -> 3 | C12: Компенсационные выплаты | G12: в размере ДО | H12: ='СВОД ФЗП'!G14 -> 2
B13: =B12+1 -> 4 | C13: Социальный налог | G13: 0.06 | H13: ='СВОД ФЗП'!H14 -> 2
B14: =B13+1 -> 5 | C14: Социальные отчисления | G14: 0.05 | H14: ='СВОД ФЗП'!I14 -> 2
B15: =B14+1 -> 6 | C15: Обязательное социальное медицинское страхование | G15: 0.03 | H15: ='СВОД ФЗП'!J14 -> 2
B16: 7 | C16: Обязательные пенсионные взносы за счет работодателя | G16: 0.035 | H16: ='СВОД ФЗП'!K14 -> 2
C18: 2. Приобретение питьевой воды для учащихся | G18: =G20 -> 1
B19: № п.п | C19: Наименование расходов | D19: Дни функционирования учреждения (дни) | E19: Количество бутылей на 2026 год | F19: Стоимость за ед. в тенге | G19: Сумма затрат в тенге
B20: 1 | C20: Вода питьевая бутилированная 18,9 л на 1186 детей | D20: 1 | E20: 1 | F20: 1 | G20: 1
B21: Расшифровка на приобретение питьевой воды для школы
B22: № | C22: Период | D22: Кол-во дней | E22: Цена | F22: Норматив на 1-го на день * (л) | G22: Количество бутылей, в 1 бутыле 18,9 (л) | H22: Сумма (тенге)
C23: Всего: | D23: =SUM(D24:D35) -> 12 | G23: =SUM(G24:G35) -> 376.50794 | H23: =SUM(H24:H35) -> 376507.94
B24: 1 | C24: Январь | D24: 1 | E24: 1000 | F24: 0.5 | G24: =1186*F24*D24/18.9 -> 31.375661 | H24: =G24*E24 -> 31375.661
B25: 2 | C25: Февраль | D25: 1 | E25: =E24 -> 1000 | F25: 0.5 | G25: =1186*F25*D25/18.9 -> 31.375661 | H25: =G25*E25 -> 31375.661
B26: 3 | C26: Март | D26: 1 | E26: =E25 -> 1000 | F26: 0.5 | G26: =1186*F26*D26/18.9 -> 31.375661 | H26: =G26*E26 -> 31375.661
B27: 4 | C27: Апрель | D27: 1 | E27: =E26 -> 1000 | F27: 0.5 | G27: =1186*F27*D27/18.9 -> 31.375661 | H27: =G27*E27 -> 31375.661
B28: 5 | C28: Май | D28: 1 | E28: =E27 -> 1000 | F28: 0.5 | G28: =1186*F28*D28/18.9 -> 31.375661 | H28: =G28*E28 -> 31375.661
B29: 6 | C29: Июнь | D29: 1 | E29: =E28 -> 1000 | F29: 0.5 | G29: =1186*F29*D29/18.9 -> 31.375661 | H29: =G29*E29 -> 31375.661
B30: 7 | C30: Июль | D30: 1 | E30: =E29 -> 1000 | F30: 0.5 | G30: =1186*F30*D30/18.9 -> 31.375661 | H30: =G30*E30 -> 31375.661
B31: 8 | C31: Август | D31: 1 | E31: =E30 -> 1000 | F31: 0.5 | G31: =1186*F31*D31/18.9 -> 31.375661 | H31: =G31*E31 -> 31375.661
B32: 9 | C32: Сентябрь | D32: 1 | E32: =E31 -> 1000 | F32: 0.5 | G32: =1186*F32*D32/18.9 -> 31.375661 | H32: =G32*E32 -> 31375.661
B33: 10 | C33: Октябрь | D33: 1 | E33: =E32 -> 1000 | F33: 0.5 | G33: =1186*F33*D33/18.9 -> 31.375661 | H33: =G33*E33 -> 31375.661
B34: 11 | C34: Ноябрь | D34: 1 | E34: =E33 -> 1000 | F34: 0.5 | G34: =1186*F34*D34/18.9 -> 31.375661 | H34: =G34*E34 -> 31375.661
B35: 12 | C35: Декабрь | D35: 1 | E35: =E34 -> 1000 | F35: 0.5 | G35: =1186*F35*D35/18.9 -> 31.375661 | H35: =G35*E35 -> 31375.661
B36: *в среднем 0,5 л на 1-го учащегося
C38: 3. Приобретение медикаментов и прочих средств медицинского назначения | H38: =G40 -> 34
B39: № п.п | C39: Наименование товаров | D39: Среднегодовое количество получателей (ед.) | E39: Дни функционирования в год (дни) | F39: Норма отпуска медикаментов на 1 единицу в день (тенге) | G39: Сумма затрат в тенге
B40: 1 | C40: Медикаменты | D40: =836+350 -> 1186 | E40: 204 | F40: =H77/204 -> 0.00014052839 | G40: =D40*E40*F40 -> 34
C41: Расшифровка расходов по медикаментам для учащихся школы
B42: № п/п | C42: Наименование | D42: Ед.измерения | E42: Кол-во, шт. | F42: Цена, тенге | G42: Итого в год, тенге | H42: Расходы по медикаментам на 1 учащегося в год, тенге
B43: 1 | C43: Адреналин 0,18 % 1 мл №5 | D43: штук | E43: 1 | F43: 1 | G43: =E43*F43 -> 1 | H43: =G43/1186 -> 0.00084317032
B44: =B43+1 -> 2 | C44: Аллервэй № 10 | D44: штук | E44: 1 | F44: 1 | G44: =E44*F44 -> 1 | H44: =G44/1186 -> 0.00084317032
B45: =B44+1 -> 3 | C45: Аммиак 10 % 20 мл | D45: штук | E45: 1 | F45: 1 | G45: =E45*F45 -> 1 | H45: =G45/1186 -> 0.00084317032
...

Sheet СВОД ФЗП
A8: Филиал НАО "Республиканская физико-математическая школа" в г.Алматы
A9: Свод по тарификационной ведомости и штатному расписанию за счет средств республиканского бюджета на 2026 год
A11: № п/п | B11: Наименование | C11: Фактическая численность един. | D11: Кол-во часов | E11: Заработная плата за месяц | F11: Годовой ФЗП за 2026 год | G11: Лечебно оздоровительные пособия | H11: Социальный налог 6% | I11: Социальные отчисления 5% | J11: Обязательное социальное медицинское схрахование 3% | K11: ОПВ 3,5% | L11: Годовой ФОТ за 2026 года с налогами (соц.налог,соц отч, мед страх, пен.взн)
A12: 1 | B12: Штатное расписание | C12: 1 | E12: 1 | F12: 1 | G12: 1 | H12: 1 | I12: 1 | J12: 1 | K12: 1 | L12: 1
A13: =A12+1 -> 2 | B13: Тарификация | C13: 1 | D13: 1 | E13: 1 | F13: 1 | G13: 1 | H13: 1 | I13: 1 | J13: 1 | K13: 1 | L13: 1
B14: ИТОГО | C14: =C12+C13 -> 2 | D14: =D12+D13 -> 1 | E14: =E12+E13 -> 2 | F14: =F12+F13 -> 2 | G14: =G12+G13 -> 2 | H14: =H12+H13 -> 2 | I14: =I12+I13 -> 2 | J14: =J12+J13 -> 2 | ... L14: =L12+L13 -> 2

Sheet Калькуляция 2026
B2: Калькуляция затрат на государственные образовательные услуги филиала НАО "Республиканская физико-математическая школа" в г.Алматы на 2026 год на одного ученика
A4: № | B4: Наименование расходов | C4: Всего на 2026 г. | D4: На одного в год | E4: На одного в месяц
A5: 1 | B5: Оплата труда | C5: ='Свод '!C10 -> 1 | D5: =C5/1186 -> 0.00084317032 | E5: =D5/12 -> 7.0264193e-05
A6: =A5+1 -> 2 | B6: Компенсационные выплаты | C6: ='Свод '!C11 -> 1 | D6: =C6/1186 -> 0.00084317032 | E6: =D6/12 -> 7.0264193e-05
A7: =A6+1 -> 3 | B7: Социальный налог | C7: ='Свод '!C12 -> 1 | D7: =C7/1186 -> 0.00084317032 | E7: =D7/12 -> 7.0264193e-05
A8: =A7+1 -> 4 | B8: Социальные отчисления | C8: ='Свод '!C13 -> 1 | D8: =C8/1186 -> 0.00084317032 | E8: =D8/12 -> 7.0264193e-05
A9: =A8+1 -> 5 | B9: Обязательное медицинское страхование | C9: ='Свод '!C14 -> 1 | D9: =C9/1186 -> 0.00084317032 | E9: =D9/12 -> 7.0264193e-05
A10: =A9+1 -> 6 | B10: Обязательные пенсионные взносы 5% | C10: ='Свод '!C15 -> 1 | D10: =C10/1186 -> 0.00084317032 | E10: =D10/12 -> 7.0264193e-05
A11: =A10+1 -> 7 | B11: Приобретение продуктов питания (питьевой воды) | C11: ='Свод '!C16 -> 1 | D11: =C11/1186 -> 0.00084317032 | E11: =D11/12 -> 7.0264193e-05
A12: =A11+1 -> 8 | B12: Приобретение горюче-смазочных материалов | C12: ='Свод '!C17 -> 1 | D12: =C12/1186 -> 0.00084317032 | E12: =D12/12 -> 7.0264193e-05
A13: =A12+1 -> 9 | B13: Приобретение медикаментов и прочих средств медицинского назначения | C13: ='Свод '!C18 -> 1 | D13: =C13/1186 -> 0.00084317032 | E13: =D13/12 -> 7.0264193e-05
A14: =A13+1 -> 10 | B14: Приобретение прочих запасов | C14: ='Свод '!C19 -> 1 | D14: =C14/1186 -> 0.00084317032 | E14: =D14/12 -> 7.0264193e-05
A15: =A14+1 -> 11 | B15: Коммунальные услуги | C15: ='Свод '!C20 -> 1 | D15: =C15/1186 -> 0.00084317032 | E15: =D15/12 -> 7.0264193e-05
A16: =A15+1 -> 12 | B16: Услуги связи и интернет | C16: ='Свод '!C21 -> 1 | D16: =C16/1186 -> 0.00084317032 | E16: =D16/12 -> 7.0264193e-05
A17: =A16+1 -> 13 | B17: Прочие услуги и работы | C17: ='Свод '!C22 -> 1 | D17: =C17/1186 -> 0.00084317032 | E17: =D17/12 -> 7.0264193e-05
... A20: =A19+1 -> 16 | B20: Прочие текущие затраты | C20: ='Свод '!C25 -> 1 | D20: =C20/1186 -> 0.00084317032 | E20: =D20/12 -> 7.0264193e-05
B21: Итого | C21: =SUM(C5:C20) -> 16 | D21: =SUM(D5:D20) -> 0.013490725 | E21: =SUM(E5:E20) -> 0.0011242271
B24: Руководитель аппарата/руководитель
B25: государственного учреждения | E25: _________________
B27: Руководитель бюджетной программы | E27: _________________
B29: Главный бухгалтер (начальник ФЭО) | E29: _________________
B31: Председатель комитета
B32: среднего образования | E32: _________________
B35: Председатель Правления НАО "РФМШ"
B37: Заместитель ПП по ФЭВ НАО "РФМШ"
B39: Гл.бухгалтер НАО "РФМШ"
B41: Экономист НАО "РФМШ"

Sheet План командир 2026
E2: Утверждаю:
E4: Директор ________________А.М. Кунгожин
E5: филиал НАО "Республиканская физико-математическая школа" в г.Алматы
K9: Утверждаю:
K10: Директор ________________М.Е.Меирбек
J11: филиал НАО "Республиканская физико-математическая школа" в г.Алматы
A13: План командировок и служебных раъездов в пределах РК на 2026 год
A15: № п/п | B15: Перечень мероприятий | C15: Пункт назначения | D15: Исходные данные | I15: Внутри РК | Q15: Организационный взнос | R15: Всего, тенге
D16: Размер МРП, тенге | E16: Кол-во поездок | F16: Кол-во дней | G16: в т.ч. кол-во дней в пути | H16: Кол-во чел. | I16: Суточные | K16: Проезд в оба конца | N16: Проживание
I17: норма МРП | J17: итого | K17: на одного туда | L17: на одного обратно | M17: итого | N17: норма МРП | P17: итого
A18: 1 | B18: Служебная поездка для участия в заклютельном этапе Республиканской олимпиады по физике и по биологии | C18: г.Алматы-г.Астана | D18: 1 | E18: 1 | F18: 1 | G18: 1 | H18: 1 | I18: 1 | J18: =I18*D18*F18*H18 -> 1 | K18: 1 | L18: 1 | M18: 1 | N18: 1 | O18: 1 | P18: 1 | Q18: 0 | R18: =J18+M18+P18+Q18 -> 3
A19: 2 | B19: Служебная поездка для участия в заклютельном этапе Республиканской олимпиады по математике и по химии | C19: г.Алматы-г.Астана | D19: 1 | E19: 1 | F19: 1 | G19: 1 | H19: 1 | I19: 1 | J19: =I19*D19*F19*H19 -> 1 | K19: 1 | L19: 1 | M19: 1 | N19: 1 | O19: 1 | P19: 1 | Q19: 0 | R19: =J19+M19+P19+Q19 -> 3
A20: =A19+1 -> 3 | B20: Служебная поездка для участия в заклютельном этапе Республиканской олимпиады по казахскому языку и летературе | C20: г.Алматы-г.Орал | D20: 1 | E20: 1 | F20: 1 | G20: 1 | H20: 1 | I20: 1 | J20: =I20*D20*F20*H20 -> 1 | K20: 1 | L20: 1 | M20: 1 | N20: 1 | O20: 1 | P20: 1 | Q20: 0 | R20: =J20+M20+P20+Q20 -> 3
A21: =A20+1 -> 4 | B21: Служебная поездка для участия в заклютельном этапе Республиканской олимпиады по русскому языку и летературе | C21: г.Алматы-г.Караганда | D21: 1 | E21: 1 | F21: 1 | G21: 1 | H21: 1 | I21: 1 | J21: =I21*D21*F21*H21 -> 1 | K21: 1 | L21: 1 | M21: 1 | N21: 1 | O21: 1 | P21: 1 | Q21: 0 | R21: =J21+M21+P21+Q21 -> 3
A22: =A21+1 -> 5 | B22: Служебная поездка для участия в заклютельном этапе Республиканской олимпиады по истории Казахстана и основы права | C22: г.Алматы-г.Кызылорда | D22: 1 | E22: 1 | F22: 1 | G22: 1 | H22: 1 | I22: 1 | J22: =I22*D22*F22*H22 -> 1 | K22: 1 | L22: 1 | M22: 1 | N22: 1 | O22: 1 | P22: 1 | Q22: 0 | R22: =J22+M22+P22+Q22 -> 3
A23: =A22+1 -> 6 | B23: Служебная поездка для участия в заклютельном этапе Республиканской олимпиады по английскому языку | C23: г.Алматы-г.Кокшетау | D23: 1 | E23: 1 | F23: 1 | G23: 1 | H23: 1 | I23: 1 | J23: =I23*D23*F23*H23 -> 1 | K23: 1 | L23: 1 | M23: 1 | N23: 1 | O23: 1 | P23: 1 | Q23: 1 | R23: =J23+M23+P23+Q23 -> 4
A24: =A23+1 -> 7 | B24: Служебная поездка для участия в заклютельном этапе Республиканской олимпиады по химии имени К.Сатпаева | C24: г.Алматы-г.Жезказган | D24: 1 | E24: 1 | F24: 1 | G24: 1 | H24: 1 | I24: 1 | J24: =I24*D24*F24*H24 -> 1 | K24: 1 | L24: 1 | M24: 1 | N24: 1 | O24: 1 | P24: 1 | Q24: 2 | R24: =J24+M24+P24+Q24 -> 5
A25: =A24+1 -> 8 | B25: Служебная поездка для участия отборочном турнире по робототехнике | C25: г.Алматы -г.Астана | D25: 1 | E25: 1 | F25: 1 | G25: 1 | H25: 1 | I25: 1 | J25: =I25*D25*F25*H25 -> 1 | K25: 1 | L25: 1 | M25: 1 | N25: 1 | O25: 1 | P25: 1 | Q25: 3 | R25: =J25+M25+P25+Q25 -> 6
A26: =A25+1 -> 9 | B26: Служебная поездка для участия в заклютельном этапе Республиканского конкурса научных проектов | C26: г.Алматы -г.Тараз | D26: 1 | E26: 1 | F26: 1 | G26: 1 | H26: 1 | I26: 1 | J26: =I26*D26*F26*H26 -> 1 | K26: 1 | L26: 1 | M26: 1 | N26: 1 | O26: 1 | P26: 1 | Q26: 4 | R26: =J26+M26+P26+Q26 -> 7
A27: =A26+1 -> 10 | B27: Служебная поездка для участия в учебно-тренировочных сборах по информатике | C27: г.Алматы-г.Астана | D27: 1 | E27: 1 | F27: 1 | G27: 1 | H27: 1 | I27: 1 | J27: =I27*D27*F27*H27 -> 1 | K27: 1 | L27: 1 | M27: 1 | N27: 1 | O27: 1 | P27: 1 | Q27: 5 | R27: =J27+M27+P27+Q27 -> 8
A28: =A27+1 -> 11 | B28: Служебная поездка для участия в Республиканской олимпиаде по каз.языку и литературе им.К.Битибаевой | C28: г.Алматы-г.Устькаменогорск | D28: 1 | E28: 1 | F28: 1 | G28: 1 | H28: 1 | I28: 1 | J28: =I28*D28*F28*H28 -> 1 | K28: 1 | L28: 1 | M28: 1 | N28: 1 | O28: 1 | P28: 1 | Q28: 6 | R28: =J28+M28+P28+Q28 -> 9
A29: =A28+1 -> 12 | B29: Служебная поездка для участия в Республиканской юниорской олимпиаде | C29: г.Алматы-г.Астана | D29: 1 | E29: 1 | F29: 1 | G29: 1 | H29: 1 | I29: 1 | J29: =I29*D29*F29*H29 -> 1 | K29: 1 | L29: 1 | M29: 1 | N29: 1 | O29: 1 | P29: 1 | Q29: 7 | R29: =J29+M29+P29+Q29 -> 10
A30: =A29+1 -> 13 | B30: Служебная поездка для участия в ежегодном турнире по робототехнике Central Asia First Global Challenge | C30: г.Алматы-г.Астана | D30: 1 | E30: 1 | F30: 1 | G30: 1 | H30: 1 | I30: 1 | J30: =I30*D30*F30*H30 -> 1 | K30: 1 | L30: 1 | M30: 1 | N30: 1 | O30: 1 | P30: 1 | Q30: 8 | R30: =J30+M30+P30+Q30 -> 11
A31: =A30+1 -> 14 | B31: Служебная поездка для участия в ХХ Президентской олимпиаде по предметам естественно-математического цикла | C31: г.Алматы -г.Астана | D31: 1 | E31: 1 | F31: 1 | G31: 1 | H31: 1 | I31: 1 | J31: =I31*D31*F31*H31 -> 1 | K31: 1 | L31: 1 | M31: 1 | N31: 1 | O31: 1 | P31: 1 | Q31: 9 | R31: =J31+M31+P31+Q31 -> 12
A32: =A31+1 -> 15 | B32: Служебная поездка для участия на встрече с Премьер-Министром РК с победителями международных олимпиад | C32: г.Алматы-г.Астана | D32: 1 | E32: 1 | F32: 1 | G32: 1 | H32: 1 | I32: 1 | J32: =I32*D32*F32*H32 -> 1 | K32: 1 | L32: 1 | M32: 1 | N32: 1 | O32: 1 | P32: 1 | Q32: 10 | R32: =J32+M32+P32+Q32 -> 13
B33: Всего : | E33: =SUM(E18:E32) -> 15 | F33: =SUM(F18:F32) -> 15 | G33: =SUM(G18:G32) -> 15 | H33: =SUM(H18:H32) -> 15 | I33: =SUM(I18:I32) -> 15 | J33: =SUM(J18:J32) -> 15 | K33: =SUM(K18:K32) -> 15 | L33: =SUM(L18:L32) -> 15 | ... R33: =SUM(R18:R32) -> 100
