Workbook
Name _Toc226895311_10: "$#ССЫЛ!.$#ССЫЛ!$#ССЫЛ!"
Name Excel_BuiltIn_Print_Titles_29: #REF!
Name Excel_BuiltIn_Print_Titles_29: #REF!
Name Excel_BuiltIn_Print_Titles_29: #REF!
Name Excel_BuiltIn_Print_Titles_29: #REF!
Name Excel_BuiltIn_Print_Titles_29: #REF!
Name k: #N/A
Name m: #N/A
Name n: #N/A
Name а: #REF!
Name а: #REF!
Name а: #REF!
Name а: #REF!
Name а: #REF!
Name аа: #REF!
Name аа: #REF!
Name аа: #REF!
Name аа: #REF!
Name аа: #REF!
Name астана: #REF!
Name астана: #REF!
Name астана: #REF!
Name астана: #REF!
Name ВидПредмета: #NAME?
Name вода: #REF!
Name вода: #REF!
Name вода: #REF!
Name вода: #REF!
Name вода: #REF!
Name г: #REF!
Name г: #REF!
Name г: #REF!
Name г: #REF!
Name г: #REF!
Name Год: #NAME?
Name Интеллектуальная_школа_Первого_Президента_физико_математического_направления_в_городе_Астана: #REF!
Name Интеллектуальная_школа_Первого_Президента_физико_математического_направления_в_городе_Астана: #REF!
Name Интеллектуальная_школа_Первого_Президента_физико_математического_направления_в_городе_Астана: #REF!
Name Интеллектуальная_школа_Первого_Президента_физико_математического_направления_в_городе_Астана: #REF!
Name Интеллектуальная_школа_Первого_Президента_физико_математического_направления_в_городе_Астана: #REF!
Name кк: #REF!
Name кк: #REF!
Name кк: #REF!
Name кк: #REF!
Name кк: #REF!
Name л: #REF!
Name л: #REF!
Name л: #REF!
Name л: #REF!
Name л: #REF!
Name ллл: #REF!
Name ллл: #REF!
Name ллл: #REF!
Name ллл: #REF!
Name ллл: #REF!
Name март: #REF!
Name март: #REF!
Name март: #REF!
Name март: #REF!
Name пнпп: #REF!

Sheet СС Алматы
B2: Сводный расчет расходов собственных средств на 2026 год
B3: филиала НАО «Республиканская физико-математическая школа» в г.Алматы
B4: За счет средств от реализации образовательных услуг на возмездной основе
F6: тенге
B7: № | C7: Наименование расходов | D7: ВСЕГО | E7: 2026 г
E8: Школа г. Алматы | F8: АО "Финансовый центр" филиал Алматы
C9: Контингент учащихся | D9: =F9 -> 164 | E9: 159 | F9: 164
B10: 1 | C10: Оплата труда работников НАО "РФМШ" | D10: 1 | E10: =D10-F10 -> 0 | F10: 1
B11: =B10+1 -> 2 | C11: Оплата труда иностранных специалистов
B12: =B11+1 -> 3 | C12: Дополнительные денежные выплаты | D12: ='СВОД общий 2026'!G11 -> 0 | E12: =D12-F12 -> 0
B13: =B12+1 -> 4 | C13: Компенсационные выплаты | D13: 1 | E13: =D13-F13 -> 1
B14: =B13+1 -> 5 | C14: Социальный налог | D14: 1 | E14: =D14-F14 -> 0 | F14: 1
B15: =B14+1 -> 6 | C15: Социальные отчисления | D15: 1 | E15: =D15-F15 -> 0 | F15: 1
B16: =B15+1 -> 7 | C16: Обязательное медицинское страхование | D16: 1 | E16: =D16-F16 -> 0 | F16: 1
B17: =B16+1 -> 8 | C17: Обязательные пенсионные взносы 3,5% за счет средств работодателя | D17: 1 | E17: =D17-F17 -> 0 | F17: 1
B18: =B17+1 -> 9 | C18: Возмещение за аренду жилого помещения | D18: 1 | E18: =D18-F18 -> 1
C19: ИТОГО ФОТ | D19: =SUM(D10:D18) -> 7 | E19: =SUM(E10:E18) -> 2 | F19: =SUM(F10:F18) -> 5
B20: =B18+1 -> 10 | C20: Приобетение продуктов питания (питьевой воды) | D20: =E20 -> 0
B21: =B20+1 -> 11 | C21: Приобретение лекарственных средств и прочих изделий медицинского назначения | D21: =E21 -> 0 | E21: ='СВОД общий 2026'!G33 -> 0
B22: =B21+1 -> 12 | C22: Приобретение топлива, горюче-смазочных материалов | D22: 1 | E22: 1
B23: =B22+1 -> 13 | C23: Приобретение прочих запасов | D23: 1 | E23: 1
B24: =B23+1 -> 14 | C24: Коммунальные услуги | D24: 1 | E24: 1
B25: =B24+1 -> 15 | C25: Оплата услуг связи | D25: 1 | E25: 1
B26: =B25+1 -> 16 | C26: Оплата прочих услуг и работ | D26: 1 | E26: 1
B27: =B26+1 -> 17 | C27: Командировка и служебные разъезды внутри страны | D27: 1 | E27: 1
B28: =B27+1 -> 18 | C28: Командировка и служебные разъезды за пределы Республики Казахстан | D28: 1 | E28: 1
B29: =B28+1 -> 19 | C29: Организация горячим пятиразовым питанием учащихся проживающих в интернате в рамках фонда всеобуча | D29: 1 | E29: 1
B30: =B29+1 -> 20 | C30: Прочие текущие затраты | D30: 1 | E30: 1
B31: =B30+1 -> 21 | C31: Приобретение машин, оборудования, инструментов, производственного и хозяйственного инвентаря | D31: 1 | E31: 1
B32: =B31+1 -> 22 | C32: Приобретение прочих основных средств (Пополнение библиотечного фонда) | D32: 1 | E32: 1
B33: =B32+1 -> 23 | C33: Прочие непредвиденные и амортизационные расходы в период финансового 2026 года | D33: =E33 -> 0 | E33: ='СВОД общий 2026'!G134 -> 0
C34: Всего расходов | D34: =SUM(D19:D33) -> 18 | E34: =SUM(E19:E33) -> 13 | F34: =SUM(F19:F33) -> 5
G77: =SUM(G79:G85) -> 702112
B83: Услуга замера сопротивления силовой и осветительной сети, контура заземления | E83: 1 | F83: =240000*1.12 -> 268800 | G83: =F83*E83 -> 268800
B84: Услуга испытания наружных пожарных лестниц | E84: 1 | F84: =100000*1.12 -> 112000 | G84: =F84*E84 -> 112000
B85: Страхование автобуса | E85: 2 | F85: 160656 | G85: =E85*F85 -> 321312
G127: =1000000-380800-95000-321312 -> 202888
G133: =G7+G77+G87+G98+G112+G103+G129+G45+G33+G41+G93+G35 -> 702112

Sheet СС Дотация
B2: Сводный расчет расходов собственных средств на 2026 год
B3: филиала НАО «Республиканская физико-математическая школа» в г.Алматы
B4: За счет средств от реализации образовательных услуг , дотация за счет средств республиканского бюджета
F6: тенге
B7: № | C7: Наименование расходов | D7: ВСЕГО | E7: 2026 г
E8: Школа г. Алматы | F8: АО "Финансовый центр" филиал Алматы
C9: Контингент учащихся | D9: =F9 -> 164 | E9: 159 | F9: 164
B10: 1 | C10: Оплата труда работников НАО "РФМШ" | D10: 1 | E10: =D10-F10 -> 0 | F10: 1
B11: =B10+1 -> 2 | C11: Оплата труда иностранных специалистов
B12: =B11+1 -> 3 | C12: Дополнительные денежные выплаты | D12: ='СВОД общий 2026'!G11 -> 0 | E12: =D12-F12 -> 0
B13: =B12+1 -> 4 | C13: Компенсационные выплаты | D13: 1 | E13: =D13-F13 -> 1
B14: =B13+1 -> 5 | C14: Социальный налог | D14: 1 | E14: =D14-F14 -> 0 | F14: 1
B15: =B14+1 -> 6 | C15: Социальные отчисления | D15: 1 | E15: =D15-F15 -> 0 | F15: 1
B16: =B15+1 -> 7 | C16: Обязательное медицинское страхование | D16: 1 | E16: =D16-F16 -> 0 | F16: 1
B17: =B16+1 -> 8 | C17: Обязательные пенсионные взносы 3,5% за счет средств работодателя | D17: 1 | E17: =D17-F17 -> 0 | F17: 1
B18: =B17+1 -> 9 | C18: Возмещение за аренду жилого помещения | D18: 1 | E18: =D18-F18 -> 1
C19: ИТОГО ФОТ | D19: =SUM(D10:D18) -> 7 | E19: =SUM(E10:E18) -> 2 | F19: =SUM(F10:F18) -> 5
B20: =B18+1 -> 10 | C20: Приобетение продуктов питания (питьевой воды) | D20: =E20 -> 0
B21: =B20+1 -> 11 | C21: Приобретение лекарственных средств и прочих изделий медицинского назначения | D21: =E21 -> 0 | E21: ='СВОД общий 2026'!G33 -> 0
B22: =B21+1 -> 12 | C22: Приобретение топлива, горюче-смазочных материалов | D22: 1 | E22: 1
B23: =B22+1 -> 13 | C23: Приобретение прочих запасов | D23: 1 | E23: 1
B24: =B23+1 -> 14 | C24: Коммунальные услуги | D24: 1 | E24: 1
B25: =B24+1 -> 15 | C25: Оплата услуг связи | D25: 1 | E25: 1
B26: =B25+1 -> 16 | C26: Оплата прочих услуг и работ | D26: 1 | E26: 1
B27: =B26+1 -> 17 | C27: Командировка и служебные разъезды внутри страны | D27: 1 | E27: 1
B28: =B27+1 -> 18 | C28: Командировка и служебные разъезды за пределы Республики Казахстан | D28: 1 | E28: 1
B29: =B28+1 -> 19 | C29: Организация горячим пятиразовым питанием учащихся проживающих в интернате в рамках фонда всеобуча | D29: 1 | E29: 1
B30: =B29+1 -> 20 | C30: Прочие текущие затраты | D30: 1 | E30: 1
B31: =B30+1 -> 21 | C31: Приобретение машин, оборудования, инструментов, производственного и хозяйственного инвентаря | D31: 1 | E31: 1
B32: =B31+1 -> 22 | C32: Приобретение прочих основных средств (Пополнение библиотечного фонда) | D32: 1 | E32: 1
B33: =B32+1 -> 23 | C33: Прочие непредвиденные и амортизационные расходы в период финансового 2026 года | D33: =E33 -> 0 | E33: ='СВОД общий 2026'!G134 -> 0
C34: Всего расходов | D34: =SUM(D19:D33) -> 18 | E34: =SUM(E19:E33) -> 13 | F34: =SUM(F19:F33) -> 5
G77: =SUM(G79:G85) -> 702112
B83: Услуга замера сопротивления силовой и осветительной сети, контура заземления | E83: 1 | F83: =240000*1.12 -> 268800 | G83: =F83*E83 -> 268800
B84: Услуга испытания наружных пожарных лестниц | E84: 1 | F84: =100000*1.12 -> 112000 | G84: =F84*E84 -> 112000
B85: Страхование автобуса | E85: 2 | F85: 160656 | G85: =E85*F85 -> 321312
G127: =1000000-380800-95000-321312 -> 202888
G133: =G7+G77+G87+G98+G112+G103+G129+G45+G33+G41+G93+G35 -> 702112

Sheet ДОХОДНАЯ ЧАСТЬ ПУ
C2: Свод дополнительной доходной части филиала НАО "РФМШ" в городе Алматы на 01 января 2026 года
B6: 3. | C6: Доходная часть филиала НАО "РФМШ" в городе Алматы за счет реализации образовательных услуг на возмездной основе на 2026 год
B7: № п/п | C7: Наименование филиала НАО "РФМШ" | D7: Классы | E7: Контингент учащихся | F7: План поступлений по месяцам на 2026 год согласно договорам с законными представителями (в тенге) | R7: Стоимость на одного в тенге | T7: Всего сумма поступлений за счет ПУ на 2026 год (тенге)
F8: январь | G8: февраль | H8: март | I8: апрель | J8: май | K8: июнь | L8: июль | M8: август | N8: сентябрь | O8: октябрь | P8: ноябрь | Q8: декабрь | R8: в месяц | S8: в год
B9: =1 -> 1 | C9: Филиал НАО "РФМШ" в г Алматы | D9: Вступ взнос 7 кл | E9: 1 | S9: 1 | T9: =E9*S9 -> 1
B10: =B9+1 -> 2 | C10: Филиал НАО "РФМШ" в г Алматы | D10: 7 классы | E10: 1 | F10: 1 | G10: 1 | H10: 1 | I10: 1 | J10: 1 | N10: 1 | O10: 1 | P10: 1 | Q10: 1 | R10: 1 | S10: 1 | T10: =F10+G10+H10+I10+J10+K10+L10+M10+N10+O10+P10+Q10 -> 9
B11: =B10+1 -> 3 | C11: Филиал НАО "РФМШ" в г Алматы | D11: с 8 по 11 кл | E11: 1 | F11: 1 | G11: 1 | H11: 1 | I11: 1 | J11: 1 | N11: 1 | O11: 1 | P11: 1 | Q11: 1 | R11: 1 | S11: 1 | T11: =F11+G11+H11+I11+J11+K11+L11+M11+N11+O11+P11+Q11 -> 9
B12: =B11+1 -> 4 | C12: Филиал НАО "РФМШ" в г Алматы Жанаозен обучение | D12: с 8 по 11 кл | E12: 1 | F12: 1 | G12: 1 | H12: 1 | I12: 1 | J12: 1 | N12: 1 | O12: 1 | P12: 1 | Q12: 1 | R12: 1 | S12: 1 | T12: =F12+G12+H12+I12+J12+K12+L12+M12+N12+O12+P12+Q12 -> 9
B13: =B12+1 -> 5 | C13: Филиал НАО "РФМШ" в г Алматы Жанаозен проживание | D13: с 8 по 11 кл | E13: 1 | F13: 1 | G13: 1 | H13: 1 | I13: 1 | J13: 1 | N13: 1 | O13: 1 | P13: 1 | Q13: 1 | R13: 1 | S13: 1 | T13: =F13+G13+H13+I13+J13+K13+L13+M13+N13+O13+P13+Q13 -> 9
B14: =B13+1 -> 6 | C14: Филиал НАО "РФМШ" в г Алматы Жанаозен питание | D14: с 8 по 11 кл | E14: 1 | F14: 1 | G14: 1 | H14: 1 | I14: 1 | J14: 1 | N14: 1 | O14: 1 | P14: 1 | Q14: 1 | R14: 1 | S14: 1 | T14: =F14+G14+H14+I14+J14+K14+L14+M14+N14+O14+P14+Q14 -> 9
B15: =B14+1 -> 7 | C15: Филиал НАО "РФМШ" в г Алматы | D15: с 10 по 11 кл АР | E15: 1 | S15: 1 | T15: =S15*E15 -> 1
B16: =B15+1 -> 8 | C16: Филиал НАО "РФМШ" в г Алматы | D16: с 10 по 11 кл АР предмет по выбору | E16: 1 | O16: 1 | P16: 1 | Q16: 1 | R16: 1 | S16: 1 | T16: =F16+G16+H16+I16+J16+K16+L16+M16+N16+O16+P16+Q16 -> 3
C17: Итого | E17: =E10+E11+E12 -> 3 | F17: =SUM(F9:F16) -> 5 | G17: =SUM(G9:G16) -> 5 | H17: =SUM(H9:H16) -> 5 | I17: =SUM(I9:I16) -> 5 | J17: =SUM(J9:J16) -> 5 | K17: =SUM(K9:K16) -> 0 | L17: =SUM(L9:L16) -> 0 | M17: =SUM(M9:M16) -> 0 | ... Q17: =SUM(Q9:Q16) -> 6 | T17: =SUM(T9:T16) -> 50
C18: Рентабельность 8% | F18: =F17*8% -> 0.4 | G18: =G17*8% -> 0.4 | H18: =H17*8% -> 0.4 | I18: =I17*8% -> 0.4 | J18: =J17*8% -> 0.4 | K18: =K17*8% -> 0 | L18: =L17*8% -> 0 | M18: =M17*8% -> 0 | ... Q18: =Q17*8% -> 0.48 | T18: =T17*8% -> 4
C19: ВСЕГО с учетом скидки и рентабельности | F19: =F17-F18 -> 4.6 | G19: =G17-G18 -> 4.6 | H19: =H17-H18 -> 4.6 | I19: =I17-I18 -> 4.6 | J19: =J17-J18 -> 4.6 | K19: =K17-K18 -> 0 | L19: =L17-L18 -> 0 | M19: =M17-M18 -> 0 | ... Q19: =Q17-Q18 -> 5.52 | T19: =T17-T18 -> 46
B20: Рентабельность 8% предусмотрена к доходной части за счет реализации образовательных услуг на возмездной основе (в случае льготных скидок и отчисляющихся учащихся при наличие задолженности)

Sheet ДОХОДНАЯ ЧАСТЬ ДТ
C2: Свод дополнительной доходной части филиала НАО "РФМШ" в городе Алматы на 01 января 2026 года
B5: 2. | C5: Доходная часть филиала НАО "РФМШ" в городе Алматы за счет средств республиканского бюджета государственный образовательный грант (ДОТАЦИЯ) на 2026 год
B6: № п/п | C6: Наименование филиала НАО "РФМШ" | D6: Классы | E6: Контингент учащихся | F6: План поступлений по месяцам на 2026 год согласно договору с АО "Финансовый центр" (в тенге) | R6: Стоимость на одного в тенге | T6: Всего сумма поступлений за счет РБ на 2026 год (тенге)
F7: январь | G7: февраль | H7: март | I7: апрель | J7: май | K7: июнь | L7: июль | M7: август | N7: сентябрь | O7: октябрь | P7: ноябрь | Q7: декабрь | R7: в месяц | S7: в год
B8: 1 | C8: Филиал НАО "РФМШ" в г Алматы | D8: с 5 по 9 кл | E8: 1 | F8: 1 | G8: 1 | H8: 1 | I8: 1 | J8: 1 | N8: 1 | O8: 1 | P8: 1 | Q8: 1 | R8: 1 | S8: 1 | T8: =F8+G8+H8+I8+J8+K8+L8+M8+N8+O8+P8+Q8 -> 9
B9: =B8+1 -> 2 | C9: Филиал НАО "РФМШ" в г Алматы | D9: с 10 по11 кл | E9: 1 | F9: 1 | G9: 1 | H9: 1 | I9: 1 | J9: 1 | N9: 1 | O9: 1 | P9: 1 | Q9: 1 | R9: 1 | S9: 1 | T9: =F9+G9+H9+I9+J9+K9+L9+M9+N9+O9+P9+Q9 -> 9
C10: Итого | E10: =SUM(E6:E9) -> 2 | F10: =SUM(F8:F9) -> 2 | G10: =SUM(G8:G9) -> 2 | H10: =SUM(H8:H9) -> 2 | I10: =SUM(I8:I9) -> 2 | J10: =SUM(J8:J9) -> 2 | K10: =SUM(K8:K9) -> 0 | L10: =SUM(L8:L9) -> 0 | M10: =SUM(M8:M9) -> 0 | ... Q10: =SUM(Q8:Q9) -> 2 | T10: =SUM(T8:T9) -> 18
B13: 4. | C13: Доходная часть филиала НАО "РФМШ" в городе Алматы за счет сторонних организаций на 2026 год
B14: № п/п | C14: Наименование арендаторов | F14: Возмещение расходов за коммунальные услуги арендаторов и аренды помещений на 2026 год (в тенге) | R14: Всего сумма поступлений на 2026 год (тенге)
F15: январь | G15: февраль | H15: март | I15: апрель | J15: май | K15: июнь | L15: июль | M15: август | N15: сентябрь | O15: октябрь | P15: ноябрь | Q15: декабрь
B16: 1 | C16: Возмещение расходов за коммунальные услуги в здании школы филиала Алматы (по ПРОГНОЗНЫМ данным) | F16: 748548.37 | G16: 1059019.1 | H16: 902400.26 | I16: 856928.33 | J16: 805131.04 | N16: 1705449.2 | O16: 1059019.1 | P16: 1059019.1 | Q16: 1059019.1 | R16: =F16+G16+H16+I16+J16+K16+L16+M16+N16+O16+P16+Q16 -> 9254533.5
B17: 2 | C17: Аренда за койко-место в интернате | H17: 778500 | I17: 0 | J17: 2250000 | K17: 41500 | L17: 1503000 | M17: 333000 | N17: 958500 | O17: 135500 | R17: =F17+G17+H17+I17+J17+K17+L17+M17+N17+O17+P17+Q17 -> 6000000
C18: Итого филиал Алматы | F18: =F16 -> 748548.37 | G18: =G16 -> 1059019.1 | H18: =H16 -> 902400.26 | I18: =I16 -> 856928.33 | J18: =J16 -> 805131.04 | K18: =K16 -> 0 | L18: =L16 -> 0 | M18: =M16 -> 0 | ... R18: =R16 -> 9254533.5

Sheet ДОХОДНАЯ ЧАСТЬ доп
C2: Свод дополнительной доходной части филиала НАО "РФМШ" в городе Алматы на 01 января 2026 года
B7: 4. | C7: Доходная часть филиала НАО "РФМШ" в городе Алматы за счет сторонних организаций на 2026 год
B8: № п/п | C8: Наименование арендаторов | F8: Возмещение расходов за коммунальные услуги арендаторов и аренды помещений на 2026 год (в тенге) | R8: Всего сумма поступлений на 2026 год (тенге)
F9: январь | G9: февраль | H9: март | I9: апрель | J9: май | K9: июнь | L9: июль | M9: август | N9: сентябрь | O9: октябрь | P9: ноябрь | Q9: декабрь
B10: 1 | C10: Возмещение расходов за коммунальные услуги в здании школы филиала Алматы (по ПРОГНОЗНЫМ данным) | F10: 1 | G10: 1 | H10: 1 | I10: 1 | J10: 1 | K10: 1 | L10: 1 | M10: 1 | N10: 1 | O10: 1 | P10: 1 | Q10: 1 | R10: =F10+G10+H10+I10+J10+K10+L10+M10+N10+O10+P10+Q10 -> 12
B11: 2 | C11: Аренда за койко-место в интернате | G11: 1 | H11: 1 | I11: 1 | J11: 1 | K11: 1 | L11: 1 | M11: 1 | N11: 1 | O11: 1 | P11: 1 | Q11: 1 | R11: =F11+G11+H11+I11+J11+K11+L11+M11+N11+O11+P11+Q11 -> 11
C12: Итого филиал Алматы | F12: =F10 -> 1 | G12: =G10 -> 1 | H12: =H10 -> 1 | I12: =I10 -> 1 | J12: =J10 -> 1 | K12: =K10 -> 1 | L12: =L10 -> 1 | M12: =M10 -> 1 | ... R12: =R10 -> 12

Sheet Свод ФОТ Алматы
B2: Свод оплаты труда филиала НАО «РФМШ» города Алматы на 01 января 2026 года
B5: 2. Свод тарификационной ведомости и штатного расписания за счет реализации образовательных услуг на возмездной основе
B6: № п/п | C6: Наименование | D6: фактическая численность един. | E6: Кол-во часов | F6: Заработная плата в месяц | G6: Годовой ФЗП на 2026 год | H6: Лечебно-оздоровительные пособие | I6: Социальный налог (11%-5%)=6% | J6: Социальные отчисления 5% | K6: Обязательное медицинское схрахование 3% | L6: ОПВР 3,5% | M6: Годовой ФОТ на 2026 года
B7: 1 | C7: Штатное расписание | D7: 1 | F7: 1 | G7: 1 | H7: 1 | I7: 1 | J7: 1 | K7: 1 | L7: 1 | M7: =G7+H7+L7+I7+J7+K7 -> 6
B8: =B7+1 -> 2 | C8: Тарификация | D8: 1 | F8: 1 | G8: 1 | H8: 1 | I8: 1 | J8: 1 | K8: 1 | L8: 1 | M8: =G8+H8+L8+I8+J8+K8 -> 6
C9: Итого | D9: =SUM(D7:D8) -> 2 | E9: =SUM(E7:E8) -> 0 | F9: =SUM(F7:F8) -> 2 | G9: =SUM(G7:G8) -> 2 | H9: =SUM(H7:H8) -> 2 | I9: =SUM(I7:I8) -> 2 | J9: =SUM(J7:J8) -> 2 | K9: =SUM(K7:K8) -> 2 | ... M9: =SUM(M7:M8) -> 12
B10: № п/п | C10: Наименование иных дополнительных выплат | D10: Количество работников | F10: Сумма в месяц | G10: Всего в год | I10: Социальный налог (11%-5%)=6% | J10: Социальные отчисления 5% | K10: Обязательное медицинское схрахование 3% | L10: ОПВР 3,5% | M10: Годовой ФОТ на 2026 года
B11: 3 | C11: Возмещение за аренду жилого помещения работникам филиала Алматы | D11: 1 | F11: 1 | G11: 1 | H11: 1 | I11: 1 | J11: 1 | K11: 1 | L11: 1 | M11: =G11+I11+J11+K11+L11 -> 5
C12: Итого | D12: =D11 -> 1 | E12: =E11 -> 0 | F12: =F11 -> 1 | G12: =G11 -> 1 | H12: =H11 -> 1 | I12: =I11 -> 1 | J12: =J11 -> 1 | K12: =K11 -> 1 | ... M12: =M11 -> 5
C13: ВСЕГО | D13: =D12+D9 -> 3 | E13: =E12+E9 -> 0 | F13: =F12+F9 -> 3 | G13: =G12+G9 -> 3 | H13: =H12+H9 -> 3 | I13: =I12+I9 -> 3 | J13: =J12+J9 -> 3 | K13: =K12+K9 -> 3 | ... M13: =M12+M9 -> 17

Sheet СВОД общий 2026
B3: Сводный расчет расходов на 2026 год
B4: ФНАО «Республиканская физико-математическая школа» в г.Алматы
B5: За счет реализации образовательных услуг на возмездной основе,
B6: также дотация за счет средств республиканского бюджета
B7: 1. Фонд Оплаты Труда (111-124) | G7: =SUM(G9:G18) -> 17
A8: № п.п | B8: Наименование расходов | G8: Сумма затрат в тенге
A9: =1 -> 1 | B9: Оплата труда штатных работников за счет реализации образовательных услуг на платной основе | G9: ='Свод ФОТ Алматы'!G7 -> 1
A10: =A9+1 -> 2 | B10: Оплата труда педагогических работников счет средств реализации образовательных услуг на платной основе | G10: ='Свод ФОТ Алматы'!G8 -> 1
A11: =A10+1 -> 3 | B11: Дополнительные денежные выплаты ПРЕМИЯ квартальная за счет средств реализации образовательных услуг на платной основе, отпускные и резервная сумма на увеличение ФОТ для педагогических и иных работников НАО "РФМШ" с 01 января 2026 года
A12: =A11+1 -> 4 | B12: Компенсационные выплаты- лечебно-оздоровительные пособия за счет средств реализации образовательных услуг на платной основе | G12: ='Свод ФОТ Алматы'!H9 -> 2
A13: =A12+1 -> 5 | B13: Социальный налог | F13: 0.06 | G13: ='Свод ФОТ Алматы'!I9 -> 2
A14: =A13+1 -> 6 | B14: Социальные отчисления | F14: 0.05 | G14: ='Свод ФОТ Алматы'!J9 -> 2
A15: =A14+1 -> 7 | B15: Обязательное социальное медицинское страхование | F15: 0.03 | G15: ='Свод ФОТ Алматы'!K9 -> 2
A16: =A15+1 -> 8 | B16: Обязательные пенсионные отчисления от работодателя 3,5% | F16: 0.035 | G16: ='Свод ФОТ Алматы'!L9 -> 2
A17: =A16+1 -> 9 | B17: Оплата труда иностранных специалистов с налоговыми выплатами филиала Астана
A18: =A17+1 -> 10 | B18: Возмещение за аренду жилого помещения сотрудникам НАО "РФМШ" | G18: ='Свод ФОТ Алматы'!M11 -> 5
B20: Расшифровка оплаты труда работникам НАО "РФМШ" за счет реализации образовательных услуг на возмездной основе
A21: № п.п | B21: Наименование | C21: фактическая численность един. | D21: кол-во часов | E21: Оплаты труда в месяц в тенге | F21: Лечебно оздоровительные пособие | G21: Итого ФОТ (тенге)
A22: 1 | B22: Штатное расписание
A23: 2 | B23: Тарификация филиала Алматы
B24: Итого | C24: =SUM(C23:C23) -> 0 | D24: =SUM(D23:D23) -> 0 | E24: =SUM(E22:E23) -> 0 | F24: =SUM(F23:F23) -> 0 | G24: =SUM(G22:G23) -> 0
A27: Расшифровка возмещений расходов за аренду жилого помещения за счет реализации образовательных услуг на возмездной основе
A28: 1 | B28: Возмещение за аренду жилого помещения работникам филиала Алматы | C28: филиал Алматы | D28: 10 | E28: ='Свод ФОТ Алматы'!F11 -> 1 | G28: ='Свод ФОТ Алматы'!M11 -> 5
B29: ИТОГО: | G29: =SUM(G28:G28) -> 5
B31: 2. Приобретение продуктов питания (питьевой воды) (141) | G31: 0
B33: 3. Приобретение медикаментов и прочих средств медицинского назначения, медицинского оборудования (142) | G33: 0
B35: 4. Приобретение топлива, горюче-смазочных материалов (144) | G35: =G37 -> 1
A36: № п/п | B36: Наименование товаров | C36: Инициатор закупа | D36: Единица измерения | E36: Кол-во, объем. | F36: Цена, средняя стоимость тенге | G36: Сумма, тенге
A37: 1 | B37: Бензин АИ 92 | C37: филиал Алматы | D37: Литр | E37: 1 | F37: 1 | G37: =E37*F37 -> 1
B39: 5. Приобретение прочих запасов (149) | G39: =SUM(G41:G43) -> 3
A40: № п/п | B40: Наименование товаров | C40: Инициатор закупа | D40: Единица измерения | E40: Кол-во, объем. | F40: Цена, средняя стоимость тенге | G40: Сумма, тенге
A41: 1 | B41: Колеса для школьного автобуса Mercedes Benz | C41: филиал Алматы | D41: штук | E41: 1 | F41: 1 | G41: =E41*F41 -> 1
A42: 2 | B42: Аккумулятор для школьного автобуса | C42: филиал Алматы | D42: штук | E42: 1 | F42: 1 | G42: =E42*F42 -> 1
A43: 3 | B43: Рукав пожарный напорный «Классик» РПК(В)-50-1, 0-УХЛ1 с головками ГР-50 Ал | C43: филиал Алматы | D43: штук | E43: 1 | F43: 1 | G43: =E43*F43 -> 1
B44: 6. Прочие услуги и работы (159) | G44: =SUM(G46:G64) -> 19
A45: № п/п | B45: Наименование товаров | C45: Инициатор закупа | D45: Единица измерения | E45: Кол-во, объем. | F45: Цена, средняя стоимость тенге | G45: Сумма, тенге
A46: 1 | B46: Услуга по обслуживанию сайта и предоставлению доступа подписания электронных договоров | C46: филиал Алматы | D46: услуга | E46: 1 | F46: 1 | G46: =E46*F46 -> 1
A47: =A46+1 -> 2 | B47: Услуги по организации и проведению учебно-тренировочного семинара ( 25 мая - завершение учебного года, 5 октября - День учителя) | C47: филиал Алматы | D47: услуга | E47: 1 | F47: 1 | G47: =E47*F47 -> 1
A48: =A47+1 -> 3 | B48: Страхование автобуса | C48: филиал Алматы | D48: услуга | E48: 1 | F48: 1 | G48: =E48*F48 -> 1
A49: =A48+1 -> 4 | B49: Обучение персонала по программе пожарно-техническому минимуму (директор и 6 зам.директора) | C49: филиал Алматы | D49: услуга | E49: 1 | F49: 1 | G49: =E49*F49 -> 1
...

Sheet График род. оплаты Алматы  
C2: График оплаты (по траншам) за образовательные услуги на платной основе
C3: для заключения договора сторонами по филиалу НАО "РФМШ" города Алматы на 2026 год
B5: № п/п | C5: Наименование и период оплаты транша | D5: Транш к оплате 7 класс (включая Жанаозен) | E5: Транш к оплате с 8-11 класс | G5: Поступления траншов 7 класс (включая Жанаозен) | I5: Поступления траншов 8-11 классы | K5: Итого по траншам | N5: 7 классы (сентябрь - декабрь) | O5: 7 классы (январь -май) | P5: 8-11 классы (сентябрь - декабрь) | Q5: 8-11 классы (январь -май) | R5: Примечание
B6: 1 | C6: Предусмотрена предоплата (гарантийный взнос) Единый размер суммы состоящий из общей стоимости образовательных услуг в течении 5 рабочих дней после подписания договора сторонами | D6: Сумма | E6: Сумма | G6: Сумма | H6: % | I6: Сумма | J6: % | K6: Сумма | L6: % | N6: =N7+O7 -> 2000000 | P6: =P7+Q7 -> 1800000
D7: 300000 | E7: 300000 | G7: =D7*N9*0.92 -> 17940000 | H7: =G7/N11*100 -> 13.8 | I7: =E7*P9*0.92 -> 28152000 | J7: =I7/P11*100 -> 15.333333 | K7: =G7+I7 -> 46092000 | L7: =(H7+J7)/2 -> 14.566667 | N7: =D11/9*4 -> 888888.89 | O7: =D11/9*5 -> 1111111.1 | P7: =E11/9*4 -> 800000 | Q7: =E11/9*5 -> 1000000 | R7: Стоимость за обучение по годам
B8: 2 | C8: Первый транш до 15 августа текущего года | D8: 600000 | E8: 500000 | G8: =D8*N9*0.92 -> 35880000 | H8: =G8/N11*100 -> 27.6 | I8: =E8*P9*0.92 -> 46920000 | J8: =I8/P11*100 -> 25.555556 | K8: =G8+I8 -> 82800000 | L8: =(H8+J8)/2 -> 26.577778 | N8: =N7/D11*100 -> 44.444444 | O8: =O7/D11*100 -> 55.555556 | P8: =P7/E11*100 -> 44.444444 | Q8: =Q7/E11*100 -> 55.555556 | R8: Размер ( %) суммы для расходов по годам
B9: 3 | C9: Второй транш до 15 ноября текущего года | D9: 600000 | E9: 500000 | G9: =D9*N9*0.92 -> 35880000 | H9: =G9/N11*100 -> 27.6 | I9: =E9*P9*0.92 -> 46920000 | J9: =I9/P11*100 -> 25.555556 | K9: =G9+I9 -> 82800000 | L9: =(H9+J9)/2 -> 26.577778 | N9: =51+14 -> 65 | O9: =51+14 -> 65 | P9: =102 -> 102 | Q9: =102 -> 102 | R9: Контингент
B10: 4 | C10: Третий транш до 15 февраля текущего года | D10: 500000 | E10: 500000 | G10: =D10*N9*0.92 -> 29900000 | H10: =G10/N11*100 -> 23 | I10: =E10*P9*0.92 -> 46920000 | J10: =I10/P11*100 -> 25.555556 | K10: =G10+I10 -> 76820000 | L10: =(H10+J10)/2 -> 24.277778 | N10: =(N9*N7) -> 57777778 | O10: =(O9*O7) -> 72222222 | P10: =(P9*P7) -> 81600000 | Q10: =(Q9*Q7) -> 102000000 | R10: Сумма дохода
B11: Итого стоимость услуги за один учебный год (9 месяцев) | D11: =SUM(D7:D10) -> 2000000 | E11: =SUM(E7:E10) -> 1800000 | G11: =G7+G8+G9+G10 -> 119600000 | H11: =(H7+H8+H9+H10) -> 92 | I11: =I7+I8+I9+I10 -> 168912000 | J11: =J7+J8+J9+J10 -> 92 | K11: =K7+K8+K9+K10 -> 288512000 | L11: =L7+L8+L9+L10 -> 92 | N11: =N10+O10 -> 1.3e+08 | P11: =P10+Q10 -> 183600000 | R11: Сумма доходов по классам
N12: =N10+P10 -> 1.3937778e+08 | R12: Сумма за сентябрь-декабрь
N13: =O10+Q10 -> 1.7422222e+08 | R13: Сумма за январь-май
N14: =N12+N13 -> 313600000 | R14: ВСЕГО
N15: =N14*8% -> 25088000 | R15: Рентабельность 8% (в случае льготных скидок и отчисляющихся учащихся при наличие задолженности)
N16: =N14-N15 -> 288512000 | R16: ВСЕГО с учетом скидки и рентабельности
C19: Главный экономист НАО «РФМШ» | G19: Каужапарова С.С.

Sheet  Калькуляция Алматы
B7: Расчет стоимости на одного за счет средств реализации образовательных услуг на платной основе на 01 января 2026 год филиал г.Алматы
B9: № | C9: Наименование расходов | D9: Калькуляция стоимости в тенге за счет реализации образовательных услуг на возмездной основе | E9: Калькуляция стоимости в тенге дотация
D10: с 5 по 11 кл | E10: с 5 по 9 кл | F10: с 10 по 11 кл
B11: 1 | C11: Оплата труда работиков НАО "РФМШ" | D11: 1 | E11: 1 | F11: 1
B12: =B11+1 -> 2 | C12: Оплата труда иностранных специалистов | D12: 1 | E12: 1 | F12: 1
B13: =B12+1 -> 3 | C13: Дополнительные денежные выплаты | D13: 1 | E13: 1 | F13: 1
B14: =B13+1 -> 4 | C14: Компенсационные выплаты | D14: 1 | E14: 1 | F14: 1
B15: =B14+1 -> 5 | C15: Социальный налог | D15: 1 | E15: 1 | F15: 1
B16: =B15+1 -> 6 | C16: Социальные отчисления | D16: 1 | E16: 1 | F16: 1
B17: =B16+1 -> 7 | C17: Обязательное медицинское страхование | D17: 1 | E17: 1 | F17: 1
B18: =B17+1 -> 8 | C18: Обязательные пенсионные взносы 2,5% за счет средств работодателя | D18: 1 | E18: 1 | F18: 1
B19: =B18+1 -> 9 | C19: Возмещение за аренду жилого помещения | D19: 1
B20: =B19+1 -> 10 | C20: Приобетение продуктов питания (питьевой воды) | D20: 1
B21: =B20+1 -> 11 | C21: Приобретение медикаментов и прочих средств медицинского назначения | D21: 1
B22: =B21+1 -> 12 | C22: Приобретение топлива, горюче-смазочных материалов | D22: 1
B23: =B22+1 -> 13 | C23: Приобретение прочих запасов | D23: 1
B24: =B23+1 -> 14 | C24: Коммунальные услуги | D24: 1
B25: =B24+1 -> 15 | C25: Услуги связи и интернет | D25: 1
B26: =B25+1 -> 16 | C26: Прочие услуги и работы | D26: 1
B27: =B26+1 -> 17 | C27: Командировка и служебные разъезды внутри страны | D27: 1
B28: =B27+1 -> 18 | C28: Командировка и служебные разъезды за пределы Республики Казахстан | D28: 1
B29: =B28+1 -> 19 | C29: Организация и обеспечение предоставления питания для учащихся | D29: 1
B30: =B29+1 -> 20 | C30: Прочие текущие затраты | D30: 1
B31: =B30+1 -> 21 | C31: ='СС Алматы'!C31 -> Приобретение машин, оборудования, инструментов, производственного и хозяйственного инвентаря | D31: 1
B32: =B31+1 -> 22 | C32: Укрепление материально-технической базы (Приобретение основных средств) | D32: 1
B33: =B32+1 -> 23 | C33: Прочие непредвиденные расходы в период финансового 2025 года | D33: 1
C34: Итого | D34: =SUM(D11:D33) -> 23 | E34: =SUM(E11:E32) -> 8 | F34: =SUM(F11:F32) -> 8
B36: Директор ФНАО РФМШ Алматы | E36: Меирбек М.Е.
B38: Экономист | E38: Куюкова Г.Е.
C39: Первый заместитель председателя правления НАО "РФМШ" | E39: Кунгожин А.М.
C41: Главный экономист НАО "РФМШ" | E41: Каужапарова С.С.

Sheet План команд в пред РК
H3: Утверждаю:
H4: Директор ________________М.Е.Меирбек
G5: филиал НАО "Республиканская физико-математическая школа" в г.Алматы
A8: План командировок и служебных разъездов в пределах РК на 2025 год
A10: № | B10: Наименование выездных мероприятий | C10: Должность | D10: Пункт назначения | E10: Суточные | J10: Проезд в оба конца | L10: Проживание | O10: Всего, тенге
E11: Размер 2 МРП, тенге | F11: Кол-во поездок | G11: Кол-во дней | H11: Кол-во чел. | I11: итого
J12: на одного | K12: итого | L12: норма 10 МРП | M12: к-во дней | N12: итого
A13: 1 | B13: Командировочные расходы и служебные разъезды в пределах Республики Казахстан (на совещание, конференции, обучающие семинары, курсы и прочие выездные мероприятия) ДИРЕКТОР в город Астана | C13: Директор | D13: Алматы/Астана | E13: 1 | F13: 1 | G13: 1 | H13: 1 | I13: 1 | J13: 1 | K13: 1 | L13: 1 | M13: 1 | N13: 1 | O13: =I13+K13+N13 -> 3
A14: 2 | B14: Командировочные расходы и служебные разъезды в пределах Республики Казахстан (на совещание, конференции, обучающие семинары, курсы и прочие выездные мероприятия) зам.директора, гл.бухгалтер, экономист, бухгалтер, юрист, специалист по закупкам, инспектор по кадрам, зав.АХЧ в город Астана | C14: Главный бухгалтер, бухгалтер, экономист, юрист, специалист по закупкам, инспектор по кадрам, зав.АХЧ | D14: Алматы/Астана | E14: 1 | F14: 1 | G14: 1 | H14: 1 | I14: 1 | J14: 1 | K14: 1 | L14: 1 | M14: 1 | N14: 1 | O14: =I14+K14+N14 -> 3
A15: 3 | B15: Расходы на проезд участников республиканских олимпиад (90 участников на весь учебный год) в города Астана, Павлодар, Тараз, Усть-Каменогорск и другие. | C15: Руководители команд | E15: 1 | F15: 1 | G15: 1 | H15: 1 | I15: 1 | J15: 1 | K15: 1 | L15: 1 | M15: 1 | N15: 1 | O15: =K15 -> 1
A16: 4 | B16: Командировочные расходы и служебные разъезды в пределах Республики Казахстана. Для участия в профессиональных конкурсах и конференциях с целью мотивации педагогического коллектива. Учителя без ограничения по предмету, администрация. | C16: Учителя, администрация | D16: Астана, Уральск, Атырау, Тараз, Шымкент и др. | E16: 1 | F16: 1 | G16: 1 | H16: 1 | I16: 1 | J16: 1 | K16: 1 | L16: 1 | M16: 1 | N16: 1 | O16: =I16+K16+N16 -> 3
B17: Всего : | G17: =SUM(G13:G16) -> 4 | H17: =SUM(H13:H16) -> 4 | I17: =SUM(I13:I16) -> 4 | J17: =SUM(J13:J16) -> 4 | K17: =SUM(K13:K16) -> 4 | L17: =SUM(L13:L16) -> 4 | M17: =SUM(M13:M16) -> 4 | N17: =SUM(N13:N16) -> 4 | O17: =SUM(O13:O16) -> 10
B21: Экономист ФНАО "РФМШ" Алматы | F21: Куюкова Г.Е.

Sheet План команд за пределы РК
H3: Утверждаю:
H4: Директор ________________М.Е.Меирбек
G5: филиал НАО "Республиканская физико-математическая школа" в г.Алматы
A8: План командировок и служебных разъездов за пределы РК на 2026 год
A10: № | B10: Наименование выездных мероприятий | C10: Должность | D10: Пункт назначения | E10: Суточные | J10: Проезд в оба конца | L10: Проживание | O10: Всего, тенге
E11: Размер 2 МРП, тенге | F11: Кол-во поездок | G11: Кол-во дней | H11: Кол-во чел. | I11: итого
J12: на одного | K12: итого | L12: норма 10 МРП | M12: к-во дней | N12: итого
A13: 1 | B13: Командировочные расходы для участия в Международной выставке образовательных технологий Bett UK в г.Лондон, Великобритания | C13: Преподовательский состав, АУП | D13: Лондон, Великобритания | E13: =3932*2 -> 7864 | F13: 1 | G13: 1 | H13: 1 | I13: 1 | J13: 1 | K13: 1 | L13: 1 | M13: 1 | N13: 1 | O13: =I13+K13+N13 -> 3
A14: 2 | B14: Командировочные расходы для участия в ежегодной профессиональной конференции в г.Сан-Диего, штат Калифорния, США - 2 сотрудника | C14: Преподовательский состав, АУП | D14: Сан-Антонио, США | E14: =3932*2 -> 7864 | F14: 1 | G14: 1 | H14: 1 | I14: 1 | J14: 1 | K14: 1 | L14: 1 | M14: 1 | N14: 1 | O14: =I14+K14+N14 -> 3
A15: 3 | B15: Командировочные расходы для участия в медународной независимой математической олимпиаде, г.Улан-Батор, Монголия | C15: Преподовательский состав, АУП | D15: Улан-Батор, Монголия | F15: 1 | G15: 1 | H15: 1 | I15: 1 | J15: 1 | K15: 1 | L15: 1 | M15: 1 | N15: 1 | O15: =I15+K15+N15 -> 3
A16: 4 | B16: Командировочные расходы для участия в межуднародной математической олимпиаде, г.Ташкент, Узбекистан | C16: Преподовательский состав, АУП | D16: Ташкент, Узбекистан | F16: 1 | G16: 1 | H16: 1 | I16: 1 | J16: 1 | K16: 1 | L16: 1 | M16: 1 | N16: 1 | O16: =I16+K16+N16 -> 3
B17: Всего : | G17: =SUM(G13:G16) -> 4 | H17: =SUM(H13:H16) -> 4 | I17: =SUM(I13:I16) -> 4 | J17: =SUM(J13:J16) -> 4 | K17: =SUM(K13:K16) -> 4 | L17: =SUM(L13:L16) -> 4 | M17: =SUM(M13:M16) -> 4 | N17: =SUM(N13:N16) -> 4 | O17: =SUM(O13:O16) -> 12
B21: Экономист ФНАО "РФМШ" Алматы | F21: Куюкова Г.Е.
