Workbook
Name _Toc226895311_10: "$#ССЫЛ!.$#ССЫЛ!$#ССЫЛ!"
Name Excel_BuiltIn_Print_Titles_29: #REF!
Name Excel_BuiltIn_Print_Titles_29: #REF!
Name Excel_BuiltIn_Print_Titles_29: #REF!
Name Excel_BuiltIn_Print_Titles_29: #REF!
Name Excel_BuiltIn_Print_Titles_29: #REF!
Name Excel_BuiltIn_Print_Titles_29: #REF!
Name Excel_BuiltIn_Print_Titles_29: #REF!
Name k: #N/A
Name m: #N/A
Name n: #N/A
Name а: #REF!
Name а: #REF!
Name а: #REF!
Name а: #REF!
Name а: #REF!
Name а: #REF!
Name а: #REF!
Name аа: #REF!
Name аа: #REF!
Name аа: #REF!
Name аа: #REF!
Name аа: #REF!
Name аа: #REF!
Name аа: #REF!
Name астана: #REF!
Name астана: #REF!
Name астана: #REF!
Name астана: #REF!
Name астана: #REF!
Name астана: #REF!
Name астана: #REF!
Name ВидПредмета: #NAME?
Name вода: #REF!
Name вода: #REF!
Name вода: #REF!
Name вода: #REF!
Name вода: #REF!
Name вода: #REF!
Name вода: #REF!
Name г: #REF!
Name г: #REF!
Name г: #REF!
Name г: #REF!
Name г: #REF!
Name г: #REF!
Name г: #REF!
Name Год: #NAME?
Name Интеллектуальная_школа_Первого_Президента_физико_математического_направления_в_городе_Астана: #REF!
Name Интеллектуальная_школа_Первого_Президента_физико_математического_направления_в_городе_Астана: #REF!
Name Интеллектуальная_школа_Первого_Президента_физико_математического_направления_в_городе_Астана: #REF!
Name Интеллектуальная_школа_Первого_Президента_физико_математического_направления_в_городе_Астана: #REF!
Name Интеллектуальная_школа_Первого_Президента_физико_математического_направления_в_городе_Астана: #REF!
Name Интеллектуальная_школа_Первого_Президента_физико_математического_направления_в_городе_Астана: #REF!
Name Интеллектуальная_школа_Первого_Президента_физико_математического_направления_в_городе_Астана: #REF!
Name кк: #REF!
Name кк: #REF!
Name кк: #REF!
Name кк: #REF!
Name кк: #REF!

Sheet сводная
G2: Приложение 51
G3: к Правилам составления и
G4: представления бюджетной заявки
B6: Сводный расчет расходов администратора
B7: бюджетных программ по бюджетным программам (подпрограммам)
I8: Коды
B9: Год | I9: 2026-2028
B10: Вид данных(прогноз, план,отчет) | I10: ПЛАН
B11: Функциональная группа | D11: Образование | I11: 4
B12: Админинистратор программ | D12: Министерство просвещения РК | I12: 224
B13: Наименование учреждения
B14: Программа | D14: Обеспечение доступности качественного школьного образования | I14: 004
B15: Подпрограмма | D15: Обучение и воспитание детей в республиканских организациях образования | I15: 100
B17: Наименование | D17: Отчет за 2024 год | F17: Утвер. план 2025г | G17: План
D18: Кассовые расходы | E18: Фактические расходы | G18: 2026г. | H18: 2027г. | I18: 2028г.
B19: 1 | D19: 2 | E19: 3 | F19: 4 | G19: 5 | H19: 6 | I19: 7
B20: 159 | C20: Всего затрат( тенге) | D20: =D21 -> 1339844102 | E20: =E21 -> 1339844102 | F20: =F21 -> 1337971668 | G20: ='Свод '!C26 -> 2.6921171e+09 | H20: ='Свод '!D26 -> 2.689948e+09 | I20: ='Свод '!E26 -> 2.6911e+09
B21: 159 | C21: Прочие услуги и работы | D21: 1339844102 | E21: 1339844102 | F21: 1337971668 | G21: =G20 -> 2.6921171e+09 | H21: =H20 -> 2.689948e+09 | I21: =I20 -> 2.6911e+09
B24: Руководитель аппарата/руководитель
B25: государственного учреждения | H25: _________________
B27: Руководитель бюджетной программы | H27: _________________
B29: Главный бухгалтер (начальник ФЭО) | H29: _________________
B31: Председатель комитета
B32: среднего образования | H32: _________________

Sheet Свод 
B2: Сводный расчет расходов на 2026-2028 годы
B5: По бюджетной программе 004 «Обеспечение доступности качественного школьного образования»
B6: по 100 подпрограмме «Обучение и воспитание детей в республиканских организациях образования»
B7: Контингент учащихся 1186
A9: № | B9: Наименование расходов | C9: 2026г | D9: 2027г | E9: 2028г
A10: 1 | B10: Оплата труда | C10: =('СВОД ФЗП'!F14) -> 1.5956226e+09 | D10: =('СВОД ФЗП'!F22) -> 1.7640392e+09 | E10: =('СВОД ФЗП'!F30) -> 1.7576817e+09
A11: =A10+1 -> 2 | B11: Компенсационные выплаты | C11: =('СВОД ФЗП'!G14) -> 1.8200077e+08 | D11: =('СВОД ФЗП'!G22) -> 1.3984083e+08 | E11: =('СВОД ФЗП'!G30) -> 1.3913335e+08
A12: =A11+1 -> 3 | B12: Обязательные пенсионные взносы 3,5% | C12: ='СВОД ФЗП'!H14 -> 66216817 | D12: ='СВОД ФЗП'!H22 -> 85732203 | E12: ='СВОД ФЗП'!H30 -> 94818193
A13: =A12+1 -> 4 | B13: Социальный налог 6% | C13: =('СВОД ФЗП'!I14) -> 1.3607012e+08 | D13: =('СВОД ФЗП'!I22) -> 98935322 | E13: =('СВОД ФЗП'!I30) -> 98567797
A14: =A13+1 -> 5 | B14: Социальные отчисления 5% | C14: =('СВОД ФЗП'!J14) -> 79993050 | D14: =('СВОД ФЗП'!J22) -> 85674603 | E14: =('СВОД ФЗП'!J30) -> 85356677
A15: =A14+1 -> 6 | B15: Обязательное социальное медицинское страхование 3% | C15: =('СВОД ФЗП'!K14) -> 53328700 | D15: =('СВОД ФЗП'!K22) -> 52921177 | E15: =('СВОД ФЗП'!K30) -> 52730451
A16: =A15+1 -> 7 | B16: Приобретение продуктов питания (питьевая вода) | C16: =('Сводная общая 2026г.'!G18) -> 2510052.9 | D16: ='Сводная общая 2027г.'!G18 -> 6400634.9 | E16: ='Сводная общая 2028г.'!G18 -> 6400634.9
A17: =A16+1 -> 8 | B17: Приобретение медикаментов и прочих средств медицинского назначения | C17: ='Сводная общая 2026г.'!H38 -> 565550 | D17: ='Сводная общая 2027г.'!H38 -> 262415 | E17: ='Сводная общая 2028г.'!H38 -> 262415
A18: =A17+1 -> 9 | B18: Приобретение горюче-смазочных материалов | C18: ='Сводная общая 2026г.'!H79 -> 531700 | D18: ='Сводная общая 2027г.'!H93 -> 702000 | E18: ='Сводная общая 2028г.'!H93 -> 702000
A19: =A18+1 -> 10 | B19: Приобретение прочих запасов | C19: =('Сводная общая 2026г.'!H84) -> 49098621 | D19: ='Сводная общая 2027г.'!H98 -> 14373593 | E19: ='Сводная общая 2028г.'!H98 -> 14373593
A20: =A19+1 -> 11 | B20: Коммунальные услуги | C20: =('Сводная общая 2026г.'!H489) -> 61221609 | D20: ='Сводная общая 2027г.'!H487 -> 41917669 | E20: ='Сводная общая 2028г.'!H487 -> 41917669
A21: =A20+1 -> 12 | B21: Услуги связи и интернет | C21: =('Сводная общая 2026г.'!H505) -> 11100000 | D21: ='Сводная общая 2027г.'!H503 -> 1781232 | E21: ='Сводная общая 2028г.'!H503 -> 1781232
A22: =A21+1 -> 13 | B22: Прочие услуги и работы | C22: =('Сводная общая 2026г.'!H509) -> 85576966 | D22: ='Сводная общая 2027г.'!H507 -> 49238591 | E22: ='Сводная общая 2028г.'!H507 -> 49238590
A23: =A22+1 -> 14 | B23: Командировки и служебные разъезды в пределах страны | C23: =('Сводная общая 2026г.'!H531) -> 5256583 | D23: ='Сводная общая 2027г.'!H528 -> 944172 | E23: ='Сводная общая 2028г.'!H528 -> 944172
A24: =A23+1 -> 15 | B24: Организация горячим пятиразовым питанием | C24: =('Сводная общая 2026г.'!G536) -> 362880000 | D24: ='Сводная общая 2027г.'!G533 -> 347040000 | E24: ='Сводная общая 2028г.'!G533 -> 347040000
A25: =A24+1 -> 16 | B25: Прочие текущие затраты | C25: =('Сводная общая 2026г.'!H561) -> 144022.5 | D25: ='Сводная общая 2027г.'!H559 -> 144355.5 | E25: ='Сводная общая 2028г.'!H559 -> 151581.6
B26: Итого | C26: =SUM(C10:C25) -> 2.6921171e+09 | D26: =SUM(D10:D25) -> 2.689948e+09 | E26: =SUM(E10:E25) -> 2.6911e+09
B28: Руководитель аппарата/руководитель
B29: государственного учреждения | E29: _________________
B31: Руководитель бюджетной программы | E31: _________________
B33: Главный бухгалтер (начальник ФЭО) | E33: _________________
B35: Председатель комитета
B36: среднего образования | E36: _________________
A38: Директор ФНАО «РФМШ» Алматы | E38: Меирбек М.Е.
A40: Экономист | E40: Куюкова Г.Е.

Sheet СВОД ФЗП
A8: Филиал НАО "Республиканская физико-математическая школа" в г.Алматы
A9: Свод по тарификационной ведомости и штатному расписанию за счет средств республиканского бюджета на 2026 год
A11: № п/п | B11: Наименование | C11: Фактическая численность един. | D11: Кол-во часов | E11: Заработная плата за месяц | F11: Годовой ФЗП за 2026 год | G11: Лечебно оздоровительные пособия | H11: ОПВ 3,5% | I11: Социальный налог 6% | J11: Социальные отчисления 5% | K11: Обязательное социальное медицинское схрахование 3% | L11: Годовой ФОТ за 2026 года с налогами (соц.налог,соц отч, мед страх, пен.взн)
A12: 1 | B12: Штатное расписание | C12: ='ШР РБ Алматы'!D173 -> 146.75 | E12: ='ШР РБ Алматы'!T173 -> 62185392 | F12: =E12*12 -> 7.4622471e+08 | G12: ='ШР РБ Алматы'!Z173 -> 1.1020807e+08 | H12: ='ШР РБ Алматы'!AB173 -> 33975147 | I12: ='ШР РБ Алматы'!AC173 -> 89432991 | J12: ='ШР РБ Алматы'!AD173 -> 38539475 | K12: ='ШР РБ Алматы'!AE173 -> 25692983 | L12: =F12+G12+H12+I12+J12+K12 -> 1.0440734e+09
A13: =A12+1 -> 2 | B13: Тарификация | C13: ='Тариф РБ Алматы'!A146 -> 123 | D13: ='Тариф РБ Алматы'!X161 -> 3031 | E13: ='Тариф РБ Алматы'!BA161 -> 70783155 | F13: =E13*12 -> 8.4939785e+08 | G13: ='Тариф РБ Алматы'!BG161 -> 71792703 | H13: ='Тариф РБ Алматы'!BI161 -> 32241670 | I13: ='Тариф РБ Алматы'!BJ161 -> 46637130 | J13: ='Тариф РБ Алматы'!BK161 -> 41453575 | K13: ='Тариф РБ Алматы'!BL161 -> 27635717 | L13: =F13+G13+H13+I13+J13+K13 -> 1.0691586e+09
B14: ИТОГО | C14: =C12+C13 -> 269.75 | D14: =D12+D13 -> 3031 | E14: =E12+E13 -> 1.3296855e+08 | F14: =F12+F13 -> 1.5956226e+09 | G14: =G12+G13 -> 1.8200077e+08 | H14: =H12+H13 -> 66216817 | I14: =I12+I13 -> 1.3607012e+08 | J14: =J12+J13 -> 79993050 | ... L14: =L12+L13 -> 2.113232e+09
A16: Филиал НАО "Республиканская физико-математическая школа" в г.Алматы
A17: Свод по тарификационной ведомости и штатному расписанию за счет средств республиканского бюджета на 2027 год
A19: № п/п | B19: Наименование | C19: Фактическая численность един. | D19: Кол-во часов | E19: Заработная плата за месяц | F19: Годовой ФЗП за 2027 год | G19: Лечебно оздоровительные пособия | H19: ОПВ 3,5% | I19: Социальный налог 6% | J19: Социальные отчисления 5% | K19: Обязательное социальное медицинское схрахование 3% | L19: Годовой ФОТ за 2027 года с налогами (соц.налог,соц отч, мед страх, пен.взн)
A20: 1 | B20: Штатное расписание | C20: 149 | E20: ='ШР 2027'!T233 -> 60679042 | F20: =E20*12 -> 7.281485e+08 | G20: ='ШР 2027'!Z233 -> 56878158 | H20: ='ШР 2027'!AE233 -> 35431380 | I20: ='ШР 2027'!AB233 -> 40796198 | J20: ='ШР 2027'!AC233 -> 35326200 | K20: ='ШР 2027'!AD233 -> 21844455 | L20: =F20+G20+I20+J20+K20+H20 -> 9.1842489e+08
A21: =A20+1 -> 2 | B21: Тарификация | C21: ='Тариф 2027'!A199 -> 149 | D21: ='Тариф 2027'!X201 -> 3843 | E21: ='Тариф 2027'!BA201 -> 86324227 | F21: =E21*12 -> 1.0358907e+09 | G21: ='Тариф 2027'!BG201 -> 82962673 | H21: ='Тариф 2027'!BL201 -> 50300822 | I21: ='Тариф 2027'!BK201 -> 58139124 | J21: ='Тариф 2027'!BI201 -> 50348403 | K21: ='Тариф 2027'!BJ201 -> 31076722 | L21: =F21+G21+I21+J21+K21+H21 -> 1.3087185e+09
B22: ИТОГО | C22: =C20+C21 -> 298 | D22: =D20+D21 -> 3843 | E22: =E20+E21 -> 1.4700327e+08 | F22: =F20+F21 -> 1.7640392e+09 | G22: =G20+G21 -> 1.3984083e+08 | H22: =H20+H21 -> 85732203 | I22: =I20+I21 -> 98935322 | J22: =J20+J21 -> 85674603 | ... L22: =L20+L21 -> 2.2271434e+09
A24: Филиал НАО "Республиканская физико-математическая школа" в г.Алматы
A25: Свод по тарификационной ведомости и штатному расписанию за счет средств республиканского бюджета на 2028 год
A27: № п/п | B27: Наименование | C27: Фактическая численность един. | D27: Кол-во часов | E27: Заработная плата за месяц | F27: Годовой ФЗП за 2028 год | G27: Лечебно оздоровительные пособия | H27: ОПВ 3,5% | I27: Социальный налог 6% | J27: Социальные отчисления 5% | K27: Обязательное социальное медицинское схрахование 3% | L27: Годовой ФОТ за 2028 года с налогами (соц.налог,соц отч, мед страх, пен.взн)
A28: 1 | B28: Штатное расписание | C28: ='ШР 2028'!D233 -> 149 | E28: ='ШР 2028'!T233 -> 60695202 | F28: =E28*12 -> 7.2834242e+08 | G28: ='ШР 2028'!Z233 -> 56878158 | H28: ='ШР 2028'!AE233 -> 39260764 | I28: ='ШР 2028'!AB233 -> 40806243 | J28: ='ШР 2028'!AC233 -> 35334926 | K28: ='ШР 2028'!AD233 -> 21850273 | L28: =F28+G28+I28+J28+K28+H28 -> 9.2247278e+08
A29: =A28+1 -> 2 | B29: Тарификация | C29: ='Тариф 2028'!A199 -> 149 | D29: ='Тариф 2028'!X201 -> 3815 | E29: ='Тариф 2028'!BA201 -> 85778272 | F29: =E29*12 -> 1.0293393e+09 | G29: ='Тариф 2028'!BG201 -> 82255191 | H29: ='Тариф 2028'!BL201 -> 55557429 | I29: ='Тариф 2028'!BK201 -> 57761554 | J29: ='Тариф 2028'!BI201 -> 50021750 | K29: ='Тариф 2028'!BJ201 -> 30880178 | L29: =F29+G29+I29+J29+K29+H29 -> 1.3058154e+09
B30: ИТОГО | C30: =C28+C29 -> 298 | D30: =D28+D29 -> 3815 | E30: =E28+E29 -> 1.4647347e+08 | F30: =F28+F29 -> 1.7576817e+09 | G30: =G28+G29 -> 1.3913335e+08 | H30: =H28+H29 -> 94818193 | I30: =I28+I29 -> 98567797 | J30: =J28+J29 -> 85356677 | ... L30: =L28+L29 -> 2.2282882e+09
B33: Экономист филиала НАО "РФМШ" в г.Алматы | K33: Куюкова Г.Е.

Sheet Сводная общая 2026г.
C3: Сводный расчет расходов на 2026 год
C4: ФНАО «Республиканская физико-математическая школа» в г.Алматы
C5: по бюджетной программе 004 «Обеспечение доступности качественного школьного образования»
C6: по 100 подпрограмме «Обучение и воспитание детей в республиканских организациях образования»
C8: 1. Фонд Оплаты Труда | H8: =H10+H11+H12+H14+H15+H16+H13 -> 2.113232e+09
B9: № п.п | C9: Наименование расходов | H9: Сумма затрат в тенге в рамках лимита
B10: 1 | C10: Штатное расписание | H10: ='СВОД ФЗП'!F12 -> 7.4622471e+08
B11: =B10+1 -> 2 | C11: Оплата труда по тарификации учителей | H11: ='СВОД ФЗП'!F13 -> 8.4939785e+08
B12: =B11+1 -> 3 | C12: Компенсационные выплаты | G12: в размере ДО | H12: ='СВОД ФЗП'!G14 -> 1.8200077e+08
B13: =B12+1 -> 4 | C13: Обязательные пенсионные взносы за счет работодателя | G13: 0.035 | H13: ='СВОД ФЗП'!H14 -> 66216817
B14: =B13+1 -> 5 | C14: Социальный налог | G14: 0.06 | H14: ='СВОД ФЗП'!I14 -> 1.3607012e+08
B15: =B14+1 -> 6 | C15: Социальные отчисления | G15: 0.05 | H15: ='СВОД ФЗП'!J14 -> 79993050
B16: =B15+1 -> 7 | C16: Обязательное социальное медицинское страхование | G16: 0.03 | H16: ='СВОД ФЗП'!K14 -> 53328700
C18: 2. Приобретение питьевой воды для учащихся | G18: =G20 -> 2510052.9
B19: № п.п | C19: Наименование расходов | D19: Дни функционирования учреждения (дни) | E19: Количество бутылей на 2026 год | F19: Стоимость за ед. в тенге | G19: Сумма затрат в тенге
B20: 1 | C20: Вода питьевая бутилированная 18,9 л на 1186 детей | D20: =D23 -> 80 | E20: =G23 -> 2510.0529 | F20: 1000 | G20: =E20*F20 -> 2510052.9
B21: Расшифровка на приобретение питьевой воды для школы
B22: № | C22: Период | D22: Кол-во дней | E22: Цена | F22: Норматив на 1-го на день * (л) | G22: Количество бутылей, в 1 бутыле 18,9 (л) | H22: Сумма (тенге)
C23: Всего: | D23: =SUM(D24:D35) -> 80 | G23: =SUM(G24:G35) -> 2510.0529 | H23: =SUM(H24:H35) -> 2510052.9
B24: 1 | C24: Январь | D24: 10 | E24: 1000 | F24: 0.5 | G24: =1186*F24*D24/18.9 -> 313.75661 | H24: =G24*E24 -> 313756.61
B25: 2 | C25: Февраль | D25: 10 | E25: =E24 -> 1000 | F25: 0.5 | G25: =1186*F25*D25/18.9 -> 313.75661 | H25: =G25*E25 -> 313756.61
B26: 3 | C26: Март | D26: 10 | E26: =E25 -> 1000 | F26: 0.5 | G26: =1186*F26*D26/18.9 -> 313.75661 | H26: =G26*E26 -> 313756.61
B27: 4 | C27: Апрель | D27: 10 | E27: =E26 -> 1000 | F27: 0.5 | G27: =1186*F27*D27/18.9 -> 313.75661 | H27: =G27*E27 -> 313756.61
B28: 5 | C28: Май | D28: 10 | E28: =E27 -> 1000 | F28: 0.5 | G28: =1186*F28*D28/18.9 -> 313.75661 | H28: =G28*E28 -> 313756.61
B29: 6 | C29: Июнь | E29: =E28 -> 1000 | F29: 0.5 | G29: =1186*F29*D29/18.9 -> 0 | H29: =G29*E29 -> 0
B30: 7 | C30: Июль | E30: =E29 -> 1000 | F30: 0.5 | G30: =1186*F30*D30/18.9 -> 0 | H30: =G30*E30 -> 0
B31: 8 | C31: Август | E31: =E30 -> 1000 | F31: 0.5 | G31: =1186*F31*D31/18.9 -> 0 | H31: =G31*E31 -> 0
B32: 9 | C32: Сентябрь | D32: 10 | E32: =E31 -> 1000 | F32: 0.5 | G32: =1186*F32*D32/18.9 -> 313.75661 | H32: =G32*E32 -> 313756.61
B33: 10 | C33: Октябрь | D33: 10 | E33: =E32 -> 1000 | F33: 0.5 | G33: =1186*F33*D33/18.9 -> 313.75661 | H33: =G33*E33 -> 313756.61
B34: 11 | C34: Ноябрь | D34: 10 | E34: =E33 -> 1000 | F34: 0.5 | G34: =1186*F34*D34/18.9 -> 313.75661 | H34: =G34*E34 -> 313756.61
B35: 12 | C35: Декабрь | E35: =E34 -> 1000 | F35: 0.5 | G35: =1186*F35*D35/18.9 -> 0 | H35: =G35*E35 -> 0
B36: *в среднем 0,5 л на 1-го учащегося
C38: 3. Приобретение медикаментов и прочих средств медицинского назначения | H38: =G40 -> 565550
B39: № п.п | C39: Наименование товаров | D39: Среднегодовое количество получателей (ед.) | E39: Дни функционирования в год (дни) | F39: Норма отпуска медикаментов на 1 единицу в день (тенге) | G39: Сумма затрат в тенге
B40: 1 | C40: Медикаменты | D40: =836+350 -> 1186 | E40: 204 | F40: =H77/204 -> 2.3375244 | G40: =D40*E40*F40 -> 565550
C41: Расшифровка расходов по медикаментам для учащихся школы
B42: № п/п | C42: Наименование | D42: Ед.измерения | E42: Кол-во, шт. | F42: Цена, тенге | G42: Итого в год, тенге | H42: Расходы по медикаментам на 1 учащегося в год, тенге
B43: 1 | C43: Адреналин 0,18 % 1 мл №5 | D43: штук | E43: 2 | F43: 2000 | G43: =E43*F43 -> 4000 | H43: =G43/1186 -> 3.3726813
B44: =B43+1 -> 2 | C44: Аллервэй № 10 | D44: штук | E44: 50 | F44: 1200 | G44: =E44*F44 -> 60000 | H44: =G44/1186 -> 50.590219
B45: =B44+1 -> 3 | C45: Аммиак 10 % 20 мл | D45: штук | E45: 5 | F45: 150 | G45: =E45*F45 -> 750 | H45: =G45/1186 -> 0.63237774
...

Sheet Сводная общая 2027г.
C3: Сводный расчет расходов на 2027 год ПЛАН
C4: ФНАО «Республиканская физико-математическая школа» в г.Алматы
C5: по бюджетной программе 004 "Обеспечение доступности качественного школьного образования"
C6: по 100 подпрограмме "Обучение и воспитание детей в республиканских организациях образования"
C8: 1. Фонд Оплаты Труда | H8: =H10+H11+H12+H13+H14+H15+H16 -> 2.2271434e+09
B9: № п.п | C9: Наименование расходов | H9: Сумма затрат в тенге в рамках лимита
B10: 1 | C10: Штатное расписание | H10: ='[1]Сводная лимит 2027г.'!H10+'[1]Сводная ДП 2027г.'!H10 -> 7.2818517e+08
B11: =B10+1 -> 2 | C11: Оплата труда по тарификации учителей | H11: ='[1]Сводная лимит 2027г.'!H11+'[1]Сводная ДП 2027г.'!H11 -> 1.0358907e+09
B12: =B11+1 -> 3 | C12: Компенсационные выплаты | G12: в размере ДО | H12: ='[1]Сводная лимит 2027г.'!H12+'[1]Сводная ДП 2027г.'!H12 -> 1.3984083e+08
B13: =B12+1 -> 4 | C13: Социальный налог | G13: 0.06 | H13: ='[1]Сводная лимит 2027г.'!H13+'[1]Сводная ДП 2027г.'!H13 -> 98937221
B14: =B13+1 -> 5 | C14: Социальные отчисления | G14: 0.05 | H14: ='[1]Сводная лимит 2027г.'!H14+'[1]Сводная ДП 2027г.'!H14 -> 85676253
B15: =B14+1 -> 6 | C15: Обязательное социальное медицинское страхование | G15: 0.03 | H15: ='[1]Сводная лимит 2027г.'!H15+'[1]Сводная ДП 2027г.'!H15 -> 52922277
B16: 7 | C16: Обязательные пенсионные взносы за счет работодателя | G16: 0.045 | H16: ='[1]Сводная лимит 2027г.'!H16+'[1]Сводная ДП 2027г.'!H16 -> 85690884
C18: 2.Приобретение питьевой воды для учащихся | G18: =G20 -> 6400634.9
B19: № п.п | C19: Наименование расходов | D19: Дни функционирования учреждения (дни) | E19: Количество бутылей на 2026 год | F19: Стоимость за ед.в тенге | G19: Сумма затрат в тенге
B20: 2 | C20: Вода питьевая бутилированная 18,9 л на 1186 детей | D20: 167 | E20: =G23 -> 6400.6349 | F20: 1000 | G20: =E20*F20 -> 6400634.9
B21: Расшифровка на приобретение питьевой воды
B22: № | C22: Период | D22: Кол-во дней | E22: Цена | F22: Норматив на 1-го на день * (л) | G22: Количество бутылей 1 бутыле 18,9 (л) | H22: Сумма (тенге)
C23: Всего: | D23: =SUM(D24:D35) -> 167 | G23: =SUM(G24:G35) -> 6400.6349 | H23: =SUM(H24:H35) -> 6400634.9
B24: 1 | C24: Январь | D24: 16 | E24: 1000 | F24: 0.5 | G24: 627.51323 | H24: =G24*E24 -> 627513.23
B25: 2 | C25: Февраль | D25: 20 | E25: 1000 | F25: 0.5 | G25: 627.51323 | H25: =G25*E25 -> 627513.23
B26: 3 | C26: Март | D26: 14 | E26: 1000 | F26: 0.5 | G26: 596.13757 | H26: =G26*E26 -> 596137.57
B27: 4 | C27: Апрель | D27: 22 | E27: 1000 | F27: 0.5 | G27: 627.51323 | H27: =G27*E27 -> 627513.23
B28: 5 | C28: Май | D28: 17 | E28: 1000 | F28: 0.5 | G28: 627.51323 | H28: =G28*E28 -> 627513.23
B29: 6 | C29: Июнь | D29: 5 | E29: 1000 | F29: 0.5 | G29: 658.88889 | H29: =G29*E29 -> 658888.89
B30: 7 | C30: Июль | E30: 1000 | F30: 0.5 | G30: 0 | H30: =G30*E30 -> 0
B31: 8 | C31: Август | E31: 1000 | F31: 0.5 | G31: 0 | H31: =G31*E31 -> 0
B32: 9 | C32: Сентябрь | D32: 22 | E32: 1000 | F32: 0.5 | G32: 658.88889 | H32: =G32*E32 -> 658888.89
B33: 10 | C33: Октябрь | D33: 21 | E33: 1000 | F33: 0.5 | G33: 658.88889 | H33: =G33*E33 -> 658888.89
B34: 11 | C34: Ноябрь | D34: 13 | E34: 1000 | F34: 0.5 | G34: 690.26455 | H34: =G34*E34 -> 690264.55
B35: 12 | C35: Декабрь | D35: 17 | E35: 1000 | F35: 0.5 | G35: 627.51323 | H35: =G35*E35 -> 627513.23
B36: *в среднем 1 л на 1-го учащегося
C38: 3. Приобретение медикаментов и прочих средств медицинского назначения | H38: =G40+G41 -> 262415
B39: № п.п | C39: Наименование товаров | D39: Среднегодовое количество получателей (ед) | E39: Дни функционирования в год (дни) | F39: Норма отпуска медикаментов на 1 единицу в день (тенге) | G39: Сумма затрат в тенге
B40: 1 | C40: Медикаменты | D40: =836+350 -> 1186 | E40: 204 | F40: =H91/204 -> 0.39651738 | G40: =D40*E40*F40 -> 95935
B41: 2 | C41: Прочие средства медицинского назначения | G41: =SUM(H45:H50) -> 166480
B43: Расшифровка расходов прочих средств медицинского назначения
B44: № п/п | C44: Наименование | D44: Характеристика товара | E44: Ед. изм. | F44: Кол-во, объём | G44: Цена за единицу, тенге | H44: Сумма, тенге
B45: 1 | C45: Омрон Термометр | E45: шт | F45: 1 | G45: 32300 | H45: =F45*G45 -> 32300
B46: 2 | C46: Тонометр UB-888 | E46: шт | F46: 1 | G46: 26000 | H46: =F46*G46 -> 26000
...

Sheet Сводная общая 2028г.
C3: Сводный расчет расходов на 2028 год ПЛАН
C4: ФНАО «Республиканская физико-математическая школа» в г.Алматы
C5: по бюджетной программе 004 "Обеспечение доступности качественного школьного образования"
C6: по 100 подпрограмме "Обучение и воспитание детей в республиканских организациях образования"
C8: 1. Фонд Оплаты Труда | H8: =H10+H11+H12+H13+H14+H15+H16 -> 2.2282882e+09
B9: № п.п | C9: Наименование расходов | H9: Сумма затрат в тенге в рамках лимита
B10: 1 | C10: Штатное расписание | H10: ='[1]Сводная лимит 2028г.'!H10+'[1]Сводная ДП 2028г.'!H10 -> 7.2828933e+08
B11: =B10+1 -> 2 | C11: Оплата труда по тарификации учителей | H11: ='[1]Сводная лимит 2028г.'!H11+'[1]Сводная ДП 2028г.'!H11 -> 1.0293393e+09
B12: =B11+1 -> 3 | C12: Компенсационные выплаты | G12: в размере ДО | H12: ='[1]Сводная лимит 2028г.'!H12+'[1]Сводная ДП 2028г.'!H12 -> 1.3913335e+08
B13: =B12+1 -> 4 | C13: Социальный налог | G13: 0.06 | H13: ='[1]Сводная лимит 2028г.'!H13+'[1]Сводная ДП 2028г.'!H13 -> 98565047
B14: =B13+1 -> 5 | C14: Социальные отчисления | G14: 0.05 | H14: ='[1]Сводная лимит 2028г.'!H14+'[1]Сводная ДП 2028г.'!H14 -> 85354287
B15: =B14+1 -> 6 | C15: Обязательное социальное медицинское страхование | G15: 0.03 | H15: ='[1]Сводная лимит 2028г.'!H15+'[1]Сводная ДП 2028г.'!H15 -> 52728858
B16: 7 | C16: Обязательные пенсионные взносы за счет работодателя | G16: 0.05 | H16: ='[1]Сводная лимит 2028г.'!H16+'[1]Сводная ДП 2028г.'!H16 -> 94878016
C18: 2.Приобретение питьевой воды для учащихся | G18: =G20 -> 6400634.9
B19: № п.п | C19: Наименование расходов | D19: Дни функционирования учреждения (дни) | E19: Количество бутылей на 2026 год | F19: Стоимость за ед.в тенге | G19: Сумма затрат в тенге
B20: 2 | C20: Вода питьевая бутилированная 18,9 л на 1186 детей | D20: 167 | E20: =G23 -> 6400.6349 | F20: 1000 | G20: =E20*F20 -> 6400634.9
B21: Расшифровка на приобретение питьевой воды
B22: № | C22: Период | D22: Кол-во дней | E22: Цена | F22: Норматив на 1-го на день * (л) | G22: Количество бутылей 1 бутыле 18,9 (л) | H22: Сумма (тенге)
C23: Всего: | D23: =SUM(D24:D35) -> 167 | G23: =SUM(G24:G35) -> 6400.6349 | H23: =SUM(H24:H35) -> 6400634.9
B24: 1 | C24: Январь | D24: 16 | E24: 1000 | F24: 0.5 | G24: 627.51323 | H24: =G24*E24 -> 627513.23
B25: 2 | C25: Февраль | D25: 20 | E25: 1000 | F25: 0.5 | G25: 627.51323 | H25: =G25*E25 -> 627513.23
B26: 3 | C26: Март | D26: 14 | E26: 1000 | F26: 0.5 | G26: 596.13757 | H26: =G26*E26 -> 596137.57
B27: 4 | C27: Апрель | D27: 22 | E27: 1000 | F27: 0.5 | G27: 627.51323 | H27: =G27*E27 -> 627513.23
B28: 5 | C28: Май | D28: 17 | E28: 1000 | F28: 0.5 | G28: 627.51323 | H28: =G28*E28 -> 627513.23
B29: 6 | C29: Июнь | D29: 5 | E29: 1000 | F29: 0.5 | G29: 658.88889 | H29: =G29*E29 -> 658888.89
B30: 7 | C30: Июль | E30: 1000 | F30: 0.5 | G30: 0 | H30: =G30*E30 -> 0
B31: 8 | C31: Август | E31: 1000 | F31: 0.5 | G31: 0 | H31: =G31*E31 -> 0
B32: 9 | C32: Сентябрь | D32: 22 | E32: 1000 | F32: 0.5 | G32: 658.88889 | H32: =G32*E32 -> 658888.89
B33: 10 | C33: Октябрь | D33: 21 | E33: 1000 | F33: 0.5 | G33: 658.88889 | H33: =G33*E33 -> 658888.89
B34: 11 | C34: Ноябрь | D34: 13 | E34: 1000 | F34: 0.5 | G34: 690.26455 | H34: =G34*E34 -> 690264.55
B35: 12 | C35: Декабрь | D35: 17 | E35: 1000 | F35: 0.5 | G35: 627.51323 | H35: =G35*E35 -> 627513.23
B36: *в среднем 1 л на 1-го учащегося
C38: 3. Приобретение медикаментов и прочих средств медицинского назначения | H38: =G40+G41 -> 262415
B39: № п.п | C39: Наименование товаров | D39: Среднегодовое количество получателей (ед) | E39: Дни функционирования в год (дни) | F39: Норма отпуска медикаментов на 1 единицу в день (тенге) | G39: Сумма затрат в тенге
B40: 1 | C40: Медикаменты | D40: =836+350 -> 1186 | E40: 204 | F40: =H91/204 -> 0.39651738 | G40: =D40*E40*F40 -> 95935
B41: 2 | C41: Прочие средства медицинского назначения | G41: =SUM(H45:H50) -> 166480
B43: Расшифровка расходов прочих средств медицинского назначения
B44: № п/п | C44: Наименование | D44: Характеристика товара | E44: Ед. изм. | F44: Кол-во, объём | G44: Цена за единицу, тенге | H44: Сумма, тенге
B45: 1 | C45: Омрон Термометр | E45: шт | F45: 1 | G45: 32300 | H45: =F45*G45 -> 32300
B46: 2 | C46: Тонометр UB-888 | E46: шт | F46: 1 | G46: 26000 | H46: =F46*G46 -> 26000
...

Sheet ШР СВОД Алматы 2026 
I5: «УТВЕРЖДЕНО»
I6: Решением Правления НАО «РФМШ»
I7: Протокол №_____ от «______» _____________ 20_____г.
A10: Штатное расписание
A11: Наименование организации: Филиал НАО «Республиканская физико-математическая школа» в г. Алматы на «01» января 2026 года
A12: (в том числе интернат )
A15: Виды доплат /согласно внутреннему Положению о системе оплаты труда работников НАО "Республиканская физико-математическая школа" заполнение в строгости с соблюдением наличие подтверждающих документов (диплом. протокол. приказ. удостоверение и иной докумен подтверждающий документ подлежащий оплате)/ строки полежат дополнению в случае необходимости
A16: № п/п | B16: Наименование должностей | C16: ФИО | D16: Количество штатных единиц | E16: Кол-во штатных единиц /по факту cогласно приказа) | F16: коэффициент | G16: Дата приема на работу/ согласно даты указанной в приказе | H16: Коэффициент для исчисления должностного оклада работников | I16: Должностной оклад/ сумма | J16: Доплата 10% за особые условия труда/ сумма | K16: Ученая степень и магистра | L16: Доплата от ДО за квалификационную категорию руковод. (директорам) и зам.руковод. | M16: Доплата от ДО за квалификацию педагогического мастерства учителей, воспитателей и иных педагогических работников | N16: Доплата от БДО за квалификационную категорию учителей, воспитателей и иных педагогических работников | O16: Доплата от БДО за класса квалификацию водителя | P16: Доплата в размере 30% от БДО за работу с библиотечным фондом, за использование дезинф.средств при уборке туалетов работниками | Q16: Доплата в размере 20% от БДО за использование дезинфицирующих средств работниками | R16: Доплата в размере 25% от БДО за особые условия труда работников | S16: Итого доплаты | T16: Всего ФЗП за месяц | U16: ОПВ 10% | V16: ИПН | W16: ВОСМС | X16: Итого на руки | Y16: Всего ФЗП в год | Z16: Лечебно-оздоровительные пособия | AA16: Всего ФЗП с леч пособием | AB16: ОПВР 3.5% | AC16: Социальный налог 6% | AD16: Социальные отчисления 5% | AE16: ОСМС 3% | AF16: ВСЕГО ФОТ | AG16: Вид бюджета
A18: Административно-управленический персонал (АУП)
A19: 1 | B19: Директор | C19: Меирбек Меирлан Едигерулы | D19: 1 | E19: 1 | G19: 45146 | H19: 80 | I19: =H19*17697 -> 1415760 | J19: =I19*10% -> 141576 | S19: =SUM(J19:R19) -> 141576 | T19: =I19+S19 -> 1557336 | U19: =T19*10% -> 155733.6 | V19: =((T19-U19-W19)-(14*4325))*10% -> 130990.57 | W19: =T19*2% -> 31146.72 | X19: =T19-U19-V19-W19 -> 1239465.1 | Y19: =T19*12 -> 18688032 | Z19: =I19*2 -> 2831520 | AA19: =Y19+Z19 -> 21519552 | AB19: =AA19*3.5% -> 753184.32 | AC19: =(AA19*0.9-(W19*12))*11%-AD19 -> 1120942.1 | AD19: =AA19*0.9*5% -> 968379.84 | AE19: =AA19*3% -> 645586.56 | AF19: =AA19+AC19+AD19+AE19+AB19 -> 25007645 | AG19: РБ
A20: =A19+1 -> 2 | B20: Заместитель директора по учебной работе | C20: Кабулова Нурбану Таргиновна | D20: 2 | E20: 1 | G20: 43395 | H20: 32 | I20: =H20*17697 -> 566304 | J20: =I20*10% -> 56630.4 | L20: =I20*50% -> 283152 | S20: =SUM(J20:R20) -> 339782.4 | T20: =I20+S20 -> 906086.4 | U20: =T20*10% -> 90608.64 | V20: =((T20-U20-W20)-(14*4325))*10% -> 73680.603 | W20: =T20*2% -> 18121.728 | X20: =T20-U20-V20-W20 -> 723675.43 | Y20: =T20*12 -> 10873037 | Z20: =I20*2 -> 1132608 | AA20: =Y20+Z20 -> 12005645 | AB20: =AA20*3.5% -> 420197.57 | AC20: =(AA20*0.9-(W20*12))*11%-AD20 -> 624384.14 | AD20: =AA20*0.9*5% -> 540254.02 | AE20: =AA20*3% -> 360169.34 | AF20: =AA20+AC20+AD20+AE20+AB20 -> 13950650 | AG20: РБ
A21: =A20+1 -> 3 | B21: Заместитель директора по учебной работе | C21: Токтасбаев Бейбарыс Ералиевич | E21: 1 | G21: 44907 | H21: 30 | I21: =H21*17697 -> 530910 | J21: =I21*10% -> 53091 | L21: =I21*30% -> 159273 | S21: =SUM(J21:R21) -> 212364 | T21: =I21+S21 -> 743274 | U21: =T21*10% -> 74327.4 | V21: =((T21-U21-W21)-(14*4325))*10% -> 59353.112 | W21: =T21*2% -> 14865.48 | X21: =T21-U21-V21-W21 -> 594728.01 | Y21: =T21*12 -> 8919288 | Z21: =I21*2 -> 1061820 | AA21: =Y21+Z21 -> 9981108 | AB21: =AA21*3.5% -> 349338.78 | AC21: =(AA21*0.9-(W21*12))*11%-AD21 -> 519357.4 | AD21: =AA21*0.9*5% -> 449149.86 | AE21: =AA21*3% -> 299433.24 | AF21: =AA21+AC21+AD21+AE21+AB21 -> 11598387 | AG21: РБ
A22: =A21+1 -> 4 | B22: Заместитель директора по воспитательной работе | C22: Жасыбаева Лазат Карбозовна | D22: 2 | E22: 1 | G22: 44844 | H22: 30 | I22: =H22*17697 -> 530910 | J22: =I22*10% -> 53091 | L22: =I22*30% -> 159273 | S22: =SUM(J22:R22) -> 212364 | T22: =I22+S22 -> 743274 | U22: =T22*10% -> 74327.4 | V22: =((T22-U22-W22)-(14*4325))*10% -> 59353.112 | W22: =T22*2% -> 14865.48 | X22: =T22-U22-V22-W22 -> 594728.01 | Y22: =T22*12 -> 8919288 | Z22: =I22*2 -> 1061820 | AA22: =Y22+Z22 -> 9981108 | AB22: =AA22*3.5% -> 349338.78 | AC22: =(AA22*0.9-(W22*12))*11%-AD22 -> 519357.4 | AD22: =AA22*0.9*5% -> 449149.86 | AE22: =AA22*3% -> 299433.24 | AF22: =AA22+AC22+AD22+AE22+AB22 -> 11598387 | AG22: РБ
A23: =A22+1 -> 5 | B23: Заместитель директора по воспитательной работе | C23: Таукебаев Куаныш Муратбекович | E23: 1 | G23: 44805 | H23: 30 | I23: =H23*17697 -> 530910 | J23: =I23*10% -> 53091 | S23: =SUM(J23:R23) -> 53091 | T23: =I23+S23 -> 584001 | U23: =T23*10% -> 58400.1 | V23: =((T23-U23-W23)-(14*4325))*10% -> 45337.088 | W23: =T23*2% -> 11680.02 | X23: =T23-U23-V23-W23 -> 468583.79 | Y23: =T23*12 -> 7008012 | Z23: =I23*2 -> 1061820 | AA23: =Y23+Z23 -> 8069832 | AB23: =AA23*3.5% -> 282444.12 | AC23: =(AA23*0.9-(W23*12))*11%-AD23 -> 420353.3 | AD23: =AA23*0.9*5% -> 363142.44 | AE23: =AA23*3% -> 242094.96 | AF23: =AA23+AC23+AD23+AE23+AB23 -> 9377866.8 | AG23: РБ
A24: =A23+1 -> 6 | B24: Заместитель директора по профильно- экспериментальной работе | C24: Бегимбетов Талгат Полатович | D24: 1 | E24: 1 | G24: 45216 | H24: 30 | I24: =H24*17697 -> 530910 | J24: =I24*10% -> 53091 | L24: =I24*30% -> 159273 | S24: =SUM(J24:R24) -> 212364 | T24: =I24+S24 -> 743274 | U24: =T24*10% -> 74327.4 | V24: =((T24-U24-W24)-(14*4325))*10% -> 59353.112 | W24: =T24*2% -> 14865.48 | X24: =T24-U24-V24-W24 -> 594728.01 | Y24: =T24*12 -> 8919288 | Z24: =I24*2 -> 1061820 | AA24: =Y24+Z24 -> 9981108 | AB24: =AA24*3.5% -> 349338.78 | AC24: =(AA24*0.9-(W24*12))*11%-AD24 -> 519357.4 | AD24: =AA24*0.9*5% -> 449149.86 | AE24: =AA24*3% -> 299433.24 | AF24: =AA24+AC24+AD24+AE24+AB24 -> 11598387 | AG24: РБ
A25: =A24+1 -> 7 | B25: Заместитель директора по научно-методической работе | C25: Аубакирова Гульнур Габдувна | D25: 1 | E25: 1 | G25: 43355 | H25: 32 | I25: =H25*17697 -> 566304 | J25: =I25*10% -> 56630.4 | L25: =I25*100% -> 566304 | S25: =SUM(J25:R25) -> 622934.4 | T25: =I25+S25 -> 1189238.4 | U25: =T25*10% -> 118923.84 | V25: =((T25-U25-W25)-(14*4325))*10% -> 98597.979 | W25: =T25*2% -> 23784.768 | X25: =T25-U25-V25-W25 -> 947931.81 | Y25: =T25*12 -> 14270861 | Z25: =I25*2 -> 1132608 | AA25: =Y25+Z25 -> 15403469 | AB25: =AA25*3.5% -> 539121.41 | AC25: =(AA25*0.9-(W25*12))*11%-AD25 -> 800391.42 | AD25: =AA25*0.9*5% -> 693156.1 | AE25: =AA25*3% -> 462104.06 | AF25: =AA25+AC25+AD25+AE25+AB25 -> 17898242 | AG25: РБ
B26: ИТОГО АУП пед работники | D26: =SUM(D19:D25) -> 7 | E26: =SUM(E19:E25) -> 7 | F26: =SUM(F19:F25) -> 0 | I26: =SUM(I19:I25) -> 4672008 | J26: =SUM(J19:J25) -> 467200.8 | K26: =SUM(K19:K25) -> 0 | L26: =SUM(L19:L25) -> 1327275 | M26: =SUM(M19:M25) -> 0 | N26: =SUM(N19:N25) -> 0 | O26: =SUM(O19:O25) -> 0 | P26: =SUM(P19:P25) -> 0 | ... AF26: =SUM(AF19:AF25) -> 1.0102957e+08
A27: =A25+1 -> 8 | B27: Заместитель директора по административно-хозяйственной работе | C27: Алин Береке Адильханович | D27: 2 | E27: 1 | G27: 42263 | H27: 35 | I27: =H27*17697 -> 619395 | J27: =I27*10% -> 61939.5 | S27: =SUM(J27:R27) -> 61939.5 | T27: =I27+S27 -> 681334.5 | U27: =T27*10% -> 68133.45 | V27: =((T27-U27-W27)-(14*4325))*10% -> 53902.436 | W27: =T27*2% -> 13626.69 | X27: =T27-U27-V27-W27 -> 545671.92 | Y27: =T27*12 -> 8176014 | Z27: =I27*2 -> 1238790 | AA27: =Y27+Z27 -> 9414804 | AB27: =AA27*3.5% -> 329518.14 | AC27: =(AA27*0.9-(W27*12))*11%-AD27 -> 490412.19 | AD27: =AA27*0.9*5% -> 423666.18 | AE27: =AA27*3% -> 282444.12 | AF27: =AA27+AC27+AD27+AE27+AB27 -> 10940845 | AG27: РБ
A28: =A27+1 -> 9 | B28: Заведующий по хозяйственной работе | C28: Камбарбаев Айдын Майсаканович | E28: 1 | G28: 44106 | H28: 24 | I28: =H28*17697 -> 424728 | J28: =I28*10% -> 42472.8 | S28: =SUM(J28:R28) -> 42472.8 | T28: =I28+S28 -> 467200.8 | U28: =T28*10% -> 46720.08 | V28: =((T28-U28-W28)-(14*4325))*10% -> 35058.67 | W28: =T28*2% -> 9344.016 | X28: =T28-U28-V28-W28 -> 376078.03 | Y28: =T28*12 -> 5606409.6 | Z28: =I28*2 -> 849456 | AA28: =Y28+Z28 -> 6455865.6 | AB28: =AA28*3.5% -> 225955.3 | AC28: =(AA28*0.9-(W28*12))*11%-AD28 -> 336282.64 | AD28: =AA28*0.9*5% -> 290513.95 | AE28: =AA28*3% -> 193675.97 | AF28: =AA28+AC28+AD28+AE28+AB28 -> 7502293.5 | AG28: РБ
A29: =A28+1 -> 10 | B29: Экономист | C29: Куюкова Гаухар Ермековна | D29: 1 | E29: 1 | G29: 44853 | H29: 30 | I29: =H29*17697 -> 530910 | J29: =I29*10% -> 53091 | S29: =SUM(J29:R29) -> 53091 | T29: =I29+S29 -> 584001 | U29: =T29*10% -> 58400.1 | V29: =((T29-U29-W29)-(14*4325))*10% -> 45337.088 | W29: =T29*2% -> 11680.02 | X29: =T29-U29-V29-W29 -> 468583.79 | Y29: =T29*12 -> 7008012 | Z29: =I29*2 -> 1061820 | AA29: =Y29+Z29 -> 8069832 | AB29: =AA29*3.5% -> 282444.12 | AC29: =(AA29*0.9-(W29*12))*11%-AD29 -> 420353.3 | AD29: =AA29*0.9*5% -> 363142.44 | AE29: =AA29*3% -> 242094.96 | AF29: =AA29+AC29+AD29+AE29+AB29 -> 9377866.8 | AG29: РБ
A30: =A29+1 -> 11 | B30: Главный бухгалтер | C30: Абулова Жулдыз Муратовна | D30: 1 | E30: 1 | G30: 43710 | H30: 35 | I30: =H30*17697 -> 619395 | J30: =I30*10% -> 61939.5 | S30: =SUM(J30:R30) -> 61939.5 | T30: =I30+S30 -> 681334.5 | U30: =T30*10% -> 68133.45 | V30: =((T30-U30-W30)-(14*4325))*10% -> 53902.436 | W30: =T30*2% -> 13626.69 | X30: =T30-U30-V30-W30 -> 545671.92 | Y30: =T30*12 -> 8176014 | Z30: =I30*2 -> 1238790 | AA30: =Y30+Z30 -> 9414804 | AB30: =AA30*3.5% -> 329518.14 | AC30: =(AA30*0.9-(W30*12))*11%-AD30 -> 490412.19 | AD30: =AA30*0.9*5% -> 423666.18 | AE30: =AA30*3% -> 282444.12 | AF30: =AA30+AC30+AD30+AE30+AB30 -> 10940845 | AG30: РБ
A31: =A30+1 -> 12 | B31: Старший бухгалтер | C31: Қожамқұлова Жанна Пірмағанбетқызы | D31: 1 | E31: 1 | G31: 44105 | H31: 30 | I31: =H31*17697 -> 530910 | J31: =I31*10% -> 53091 | S31: =SUM(J31:R31) -> 53091 | T31: =I31+S31 -> 584001 | U31: =T31*10% -> 58400.1 | V31: =((T31-U31-W31)-(14*4325))*10% -> 45337.088 | W31: =T31*2% -> 11680.02 | X31: =T31-U31-V31-W31 -> 468583.79 | Y31: =T31*12 -> 7008012 | Z31: =I31*2 -> 1061820 | AA31: =Y31+Z31 -> 8069832 | AB31: =AA31*3.5% -> 282444.12 | AC31: =(AA31*0.9-(W31*12))*11%-AD31 -> 420353.3 | AD31: =AA31*0.9*5% -> 363142.44 | AE31: =AA31*3% -> 242094.96 | AF31: =AA31+AC31+AD31+AE31+AB31 -> 9377866.8 | AG31: РБ
A32: =A31+1 -> 13 | B32: Бухгалтер | C32: Сабирова Гулжан Саухановна | D32: 2 | E32: 1 | G32: 44939 | H32: 23 | I32: =H32*17697 -> 407031 | J32: =I32*10% -> 40703.1 | S32: =SUM(J32:R32) -> 40703.1 | T32: =I32+S32 -> 447734.1 | U32: =T32*10% -> 44773.41 | V32: =((T32-U32-W32)-(14*4325))*10% -> 33345.601 | W32: =T32*2% -> 8954.682 | X32: =T32-U32-V32-W32 -> 360660.41 | Y32: =T32*12 -> 5372809.2 | Z32: =I32*2 -> 814062 | AA32: =Y32+Z32 -> 6186871.2 | AB32: =AA32*3.5% -> 216540.49 | AC32: =(AA32*0.9-(W32*12))*11%-AD32 -> 322270.86 | AD32: =AA32*0.9*5% -> 278409.2 | AE32: =AA32*3% -> 185606.14 | AF32: =AA32+AC32+AD32+AE32+AB32 -> 7189697.9 | AG32: РБ
A33: =A32+1 -> 14 | B33: Бухгалтер | C33: Каныбетова Балжан Сериковна | E33: 1 | G33: 41860 | H33: 23 | I33: =H33*17697 -> 407031 | J33: =I33*10% -> 40703.1 | S33: =SUM(J33:R33) -> 40703.1 | T33: =I33+S33 -> 447734.1 | U33: =T33*10% -> 44773.41 | V33: =((T33-U33-W33)-(14*4325))*10% -> 33345.601 | W33: =T33*2% -> 8954.682 | X33: =T33-U33-V33-W33 -> 360660.41 | Y33: =T33*12 -> 5372809.2 | Z33: =I33*2 -> 814062 | AA33: =Y33+Z33 -> 6186871.2 | AB33: =AA33*3.5% -> 216540.49 | AC33: =(AA33*0.9-(W33*12))*11%-AD33 -> 322270.86 | AD33: =AA33*0.9*5% -> 278409.2 | AE33: =AA33*3% -> 185606.14 | AF33: =AA33+AC33+AD33+AE33+AB33 -> 7189697.9 | AG33: РБ
A34: =A33+1 -> 15 | B34: Специалист по закупкам | C34: Жанабилов Жандос Ерболатович | D34: 1 | E34: 1 | G34: 45019 | H34: 28 | I34: =H34*17697 -> 495516 | J34: =I34*10% -> 49551.6 | S34: =SUM(J34:R34) -> 49551.6 | T34: =I34+S34 -> 545067.6 | U34: =T34*10% -> 54506.76 | V34: =((T34-U34-W34)-(14*4325))*10% -> 41910.949 | W34: =T34*2% -> 10901.352 | X34: =T34-U34-V34-W34 -> 437748.54 | Y34: =T34*12 -> 6540811.2 | Z34: =I34*2 -> 991032 | AA34: =Y34+Z34 -> 7531843.2 | AB34: =AA34*3.5% -> 263614.51 | AC34: =(AA34*0.9-(W34*12))*11%-AD34 -> 392329.75 | AD34: =AA34*0.9*5% -> 338932.94 | AE34: =AA34*3% -> 225955.3 | AF34: =AA34+AC34+AD34+AE34+AB34 -> 8752675.7 | AG34: РБ
A35: =A34+1 -> 16 | B35: Юрист | C35: Токсеитова Гульмира Назымбековна | D35: 1 | E35: 1 | G35: 45232 | H35: 28 | I35: =H35*17697 -> 495516 | J35: =I35*10% -> 49551.6 | S35: =SUM(J35:R35) -> 49551.6 | T35: =I35+S35 -> 545067.6 | U35: =T35*10% -> 54506.76 | V35: =((T35-U35-W35)-(14*4325))*10% -> 41910.949 | W35: =T35*2% -> 10901.352 | X35: =T35-U35-V35-W35 -> 437748.54 | Y35: =T35*12 -> 6540811.2 | Z35: =I35*2 -> 991032 | AA35: =Y35+Z35 -> 7531843.2 | AB35: =AA35*3.5% -> 263614.51 | AC35: =(AA35*0.9-(W35*12))*11%-AD35 -> 392329.75 | AD35: =AA35*0.9*5% -> 338932.94 | AE35: =AA35*3% -> 225955.3 | AF35: =AA35+AC35+AD35+AE35+AB35 -> 8752675.7 | AG35: РБ
A36: =A35+1 -> 17 | B36: Инспектор по кадрам | C36: Асылова Куралай Мухаметкалиевна | D36: 1 | E36: 1 | G36: 42980 | H36: 25 | I36: =H36*17697 -> 442425 | J36: =I36*10% -> 44242.5 | S36: =SUM(J36:R36) -> 44242.5 | T36: =I36+S36 -> 486667.5 | U36: =T36*10% -> 48666.75 | V36: =((T36-U36-W36)-(14*4325))*10% -> 36771.74 | W36: =T36*2% -> 9733.35 | X36: =T36-U36-V36-W36 -> 391495.66 | Y36: =T36*12 -> 5840010 | Z36: =I36*2 -> 884850 | AA36: =Y36+Z36 -> 6724860 | AB36: =AA36*3.5% -> 235370.1 | AC36: =(AA36*0.9-(W36*12))*11%-AD36 -> 350294.42 | AD36: =AA36*0.9*5% -> 302618.7 | AE36: =AA36*3% -> 201745.8 | AF36: =AA36+AC36+AD36+AE36+AB36 -> 7814889 | AG36: РБ
A37: =A36+1 -> 18 | B37: Секретарь | C37: Жупбаева Жулдуз Ибраимовна | D37: 1 | E37: 1 | G37: 44305 | H37: 22 | I37: =H37*17697 -> 389334 | J37: =I37*10% -> 38933.4 | S37: =SUM(J37:R37) -> 38933.4 | T37: =I37+S37 -> 428267.4 | U37: =T37*10% -> 42826.74 | V37: =((T37-U37-W37)-(14*4325))*10% -> 31632.531 | W37: =T37*2% -> 8565.348 | X37: =T37-U37-V37-W37 -> 345242.78 | Y37: =T37*12 -> 5139208.8 | Z37: =I37*2 -> 778668 | AA37: =Y37+Z37 -> 5917876.8 | AB37: =AA37*3.5% -> 207125.69 | AC37: =(AA37*0.9-(W37*12))*11%-AD37 -> 308259.09 | AD37: =AA37*0.9*5% -> 266304.46 | AE37: =AA37*3% -> 177536.3 | AF37: =AA37+AC37+AD37+AE37+AB37 -> 6877102.3 | AG37: РБ
A38: =A37+1 -> 19 | B38: Архивариус | C38: Ермеккалиева Тлектес Сансизбаевна | D38: 1 | E38: 1 | G38: 42888 | H38: 13 | I38: =H38*17697 -> 230061 | J38: =I38*10% -> 23006.1 | S38: =SUM(J38:R38) -> 23006.1 | T38: =I38+S38 -> 253067.1 | U38: =T38*10% -> 25306.71 | V38: =((T38-U38-W38)-(14*4325))*10% -> 16214.905 | W38: =T38*2% -> 5061.342 | X38: =T38-U38-V38-W38 -> 206484.14 | Y38: =T38*12 -> 3036805.2 | Z38: =I38*2 -> 460122 | AA38: =Y38+Z38 -> 3496927.2 | AB38: =AA38*3.5% -> 122392.45 | AC38: =(AA38*0.9-(W38*12))*11%-AD38 -> 182153.1 | AD38: =AA38*0.9*5% -> 157361.72 | AE38: =AA38*3% -> 104907.82 | AF38: =AA38+AC38+AD38+AE38+AB38 -> 4063742.3 | AG38: РБ
B39: ИТОГО АУП без пед .работников | D39: =SUM(D27:D38) -> 12 | E39: =SUM(E27:E38) -> 12 | I39: =SUM(I27:I38) -> 5592252 | J39: =SUM(J27:J38) -> 559225.2 | K39: =SUM(K27:K38) -> 0 | L39: =SUM(L27:L38) -> 0 | M39: =SUM(M27:M38) -> 0 | N39: =SUM(N27:N38) -> 0 | O39: =SUM(O27:O38) -> 0 | P39: =SUM(P27:P38) -> 0 | ... AF39: =SUM(AF27:AF38) -> 98780197
B40: ВСЕГО по АУП | D40: =D26+D39 -> 19 | E40: =E26+E39 -> 19 | I40: =I26+I39 -> 10264260 | J40: =J26+J39 -> 1026426 | K40: =K26+K39 -> 0 | L40: =L26+L39 -> 1327275 | M40: =M26+M39 -> 0 | N40: =N26+N39 -> 0 | O40: =O26+O39 -> 0 | P40: =P26+P39 -> 0 | ... AF40: =AF26+AF39 -> 1.9980976e+08
A41: Учебно-вспомогательный персонал (УВП)
A42: =A38+1 -> 20 | B42: Консультант по профессиональной ориентации | C42: Амангельдина Айгерім Санатқызы | D42: 4 | E42: 1 | F42: 17697 | G42: 45902 | H42: 32 | I42: =E42*17697*H42 -> 566304 | J42: =I42*10% -> 56630.4 | S42: =SUM(J42:R42) -> 56630.4 | T42: =I42+S42 -> 622934.4 | U42: =T42*10% -> 62293.44 | V42: =((T42-U42-W42)-(14*4325))*10% -> 48763.227 | W42: =T42*2% -> 12458.688 | X42: =T42-U42-V42-W42 -> 499419.04 | Y42: =T42*12 -> 7475212.8 | Z42: =I42*2 -> 1132608 | AA42: =Y42+Z42 -> 8607820.8 | AB42: =AA42*3.5% -> 301273.73 | AC42: =(AA42*0.9-(W42*12))*11%-AD42 -> 448376.86 | AD42: =AA42*0.9*5% -> 387351.94 | AE42: =AA42*3% -> 258234.62 | AF42: =AA42+AC42+AD42+AE42+AB42 -> 10003058 | AG42: РБ
A43: =A42+1 -> 21 | B43: Консультант по профессиональной ориентации | C43: Вакансия-1 | F43: 17697 | G43: 45300 | H43: 70 | I43: =17697*H43 -> 1238790 | J43: =I43*10% -> 123879 | S43: =SUM(J43:R43) -> 123879 | T43: =I43+S43 -> 1362669 | U43: =T43*10% -> 136266.9 | V43: =((T43-U43-W43)-(14*4325))*10% -> 113859.87 | W43: =T43*2% -> 27253.38 | X43: =T43-U43-V43-W43 -> 1085288.8 | Y43: =T43*12 -> 16352028 | Z43: =I43*2 -> 2477580 | AA43: =Y43+Z43 -> 18829608 | AB43: =AA43*3.5% -> 659036.28 | AC43: =(AA43*0.9-(W43*12))*11%-AD43 -> 980824.37 | AD43: =AA43*0.9*5% -> 847332.36 | AE43: =AA43*3% -> 564888.24 | AF43: =AA43+AC43+AD43+AE43+AB43 -> 21881689 | AG43: РБ
A44: =A43+1 -> 22 | B44: Консультант по профессиональной ориентации | C44: Мақашева Нұрила Болатқызы | E44: 1 | F44: 17697 | G44: 45902 | H44: 32 | I44: =17697*H44 -> 566304 | J44: =I44*10% -> 56630.4 | S44: =SUM(J44:R44) -> 56630.4 | T44: =I44+S44 -> 622934.4 | U44: =T44*10% -> 62293.44 | V44: =((T44-U44-W44)-(14*4325))*10% -> 48763.227 | W44: =T44*2% -> 12458.688 | X44: =T44-U44-V44-W44 -> 499419.04 | Y44: =T44*12 -> 7475212.8 | Z44: =I44*2 -> 1132608 | AA44: =Y44+Z44 -> 8607820.8 | AB44: =AA44*3.5% -> 301273.73 | AC44: =(AA44*0.9-(W44*12))*11%-AD44 -> 448376.86 | AD44: =AA44*0.9*5% -> 387351.94 | AE44: =AA44*3% -> 258234.62 | AF44: =AA44+AC44+AD44+AE44+AB44 -> 10003058 | AG44: РБ
A45: =A44+1 -> 23 | B45: Консультант по профессиональной ориентации | C45: Муратова Алина Кабыловна | E45: 1 | F45: 17697 | G45: 45902 | H45: 27 | I45: =17697*H45 -> 477819 | J45: =I45*10% -> 47781.9 | S45: =SUM(J45:R45) -> 47781.9 | T45: =I45+S45 -> 525600.9 | U45: =T45*10% -> 52560.09 | V45: =((T45-U45-W45)-(14*4325))*10% -> 40197.879 | W45: =T45*2% -> 10512.018 | X45: =T45-U45-V45-W45 -> 422330.91 | Y45: =T45*12 -> 6307210.8 | Z45: =I45*2 -> 955638 | AA45: =Y45+Z45 -> 7262848.8 | AB45: =AA45*3.5% -> 254199.71 | AC45: =(AA45*0.9-(W45*12))*11%-AD45 -> 378317.97 | AD45: =AA45*0.9*5% -> 326828.2 | AE45: =AA45*3% -> 217885.46 | AF45: =AA45+AC45+AD45+AE45+AB45 -> 8440080.1 | AG45: РБ
A46: =A45+1 -> 24 | B46: Менеджер УР | C46: Ахметова Алия Нуртаевна | D46: 6 | E46: 1 | F46: 17697 | G46: 43078 | H46: 22 | I46: =E46*17697*H46 -> 389334 | J46: =I46*10% -> 38933.4 | S46: =SUM(J46:R46) -> 38933.4 | T46: =I46+S46 -> 428267.4 | U46: =T46*10% -> 42826.74 | V46: =((T46-U46-W46)-(14*4325))*10% -> 31632.531 | W46: =T46*2% -> 8565.348 | X46: =T46-U46-V46-W46 -> 345242.78 | Y46: =T46*12 -> 5139208.8 | Z46: =I46*2 -> 778668 | AA46: =Y46+Z46 -> 5917876.8 | AB46: =AA46*3.5% -> 207125.69 | AC46: =(AA46*0.9-(W46*12))*11%-AD46 -> 308259.09 | AD46: =AA46*0.9*5% -> 266304.46 | AE46: =AA46*3% -> 177536.3 | AF46: =AA46+AC46+AD46+AE46+AB46 -> 6877102.3 | AG46: РБ
A47: =A46+1 -> 25 | B47: Менеджер УР | C47: Абдыкаримова Акерке Маратовна | E47: 1 | F47: 17697 | G47: 45891 | H47: 17 | I47: =E47*17697*H47 -> 300849 | J47: =I47*10% -> 30084.9 | S47: =SUM(J47:R47) -> 30084.9 | T47: =I47+S47 -> 330933.9 | U47: =T47*10% -> 33093.39 | V47: =((T47-U47-W47)-(14*4325))*10% -> 23067.183 | W47: =T47*2% -> 6618.678 | X47: =T47-U47-V47-W47 -> 268154.65 | Y47: =T47*12 -> 3971206.8 | Z47: =I47*2 -> 601698 | AA47: =Y47+Z47 -> 4572904.8 | AB47: =AA47*3.5% -> 160051.67 | AC47: =(AA47*0.9-(W47*12))*11%-AD47 -> 238200.2 | AD47: =AA47*0.9*5% -> 205780.72 | AE47: =AA47*3% -> 137187.14 | AF47: =AA47+AC47+AD47+AE47+AB47 -> 5314124.5 | AG47: РБ
A48: =A47+1 -> 26 | B48: Менеджер УР | C48: Нусибақын Аружан Ерболқызы | E48: 1 | F48: 17697 | G48: 45904 | H48: 17 | I48: =E48*17697*H48 -> 300849 | J48: =I48*10% -> 30084.9 | S48: =SUM(J48:R48) -> 30084.9 | T48: =I48+S48 -> 330933.9 | U48: =T48*10% -> 33093.39 | V48: =((T48-U48-W48)-(14*4325))*10% -> 23067.183 | W48: =T48*2% -> 6618.678 | X48: =T48-U48-V48-W48 -> 268154.65 | Y48: =T48*12 -> 3971206.8 | Z48: =I48*2 -> 601698 | AA48: =Y48+Z48 -> 4572904.8 | AB48: =AA48*3.5% -> 160051.67 | AC48: =(AA48*0.9-(W48*12))*11%-AD48 -> 238200.2 | AD48: =AA48*0.9*5% -> 205780.72 | AE48: =AA48*3% -> 137187.14 | AF48: =AA48+AC48+AD48+AE48+AB48 -> 5314124.5 | AG48: РБ
A49: =A48+1 -> 27 | B49: Менеджер УР | C49: Вакансия-2 | F49: 17697 | H49: 35 | I49: =2*17697*H49 -> 1238790 | J49: =I49*10% -> 123879 | S49: =SUM(J49:R49) -> 123879 | T49: =I49+S49 -> 1362669 | U49: =T49*10% -> 136266.9 | V49: =((T49-U49-W49)-(14*4325))*10% -> 113859.87 | W49: =T49*2% -> 27253.38 | X49: =T49-U49-V49-W49 -> 1085288.8 | Y49: =T49*12 -> 16352028 | Z49: =I49*2 -> 2477580 | AA49: =Y49+Z49 -> 18829608 | AB49: =AA49*3.5% -> 659036.28 | AC49: =(AA49*0.9-(W49*12))*11%-AD49+5000000 -> 5980824.4 | AD49: =AA49*0.9*5% -> 847332.36 | AE49: =AA49*3% -> 564888.24 | AF49: =AA49+AC49+AD49+AE49+AB49 -> 26881689 | AG49: РБ
...

Sheet ШР РБ Алматы
I5: «УТВЕРЖДЕНО»
I6: Решением Правления НАО «РФМШ»
I7: Протокол №_____ от «______» _____________ 20_____г.
A10: Штатное расписание
A11: Наименование организации: Филиал НАО «Республиканская физико-математическая школа» в г. Алматы на «01» января 2026 года
A12: (в том числе интернат )
A15: Виды доплат /согласно внутреннему Положению о системе оплаты труда работников НАО "Республиканская физико-математическая школа" заполнение в строгости с соблюдением наличие подтверждающих документов (диплом. протокол. приказ. удостоверение и иной докумен подтверждающий документ подлежащий оплате)/ строки полежат дополнению в случае необходимости
A16: № п/п | B16: Наименование должностей | C16: ФИО | D16: Количество штатных единиц | E16: Кол-во штатных единиц /по факту cогласно приказа) | F16: коэффициент | G16: Дата приема на работу/ согласно даты указанной в приказе | H16: Коэффициент для исчисления должностного оклада работников | I16: Должностной оклад/ сумма | J16: Доплата 10% за особые условия труда/ сумма | K16: Ученая степень и магистра | L16: Доплата от ДО за квалификационную категорию руковод. (директорам) и зам.руковод. | M16: Доплата от ДО за квалификацию педагогического мастерства учителей, воспитателей и иных педагогических работников | N16: Доплата от БДО за квалификационную категорию учителей, воспитателей и иных педагогических работников | O16: Доплата от БДО за класса квалификацию водителя | P16: Доплата в размере 30% от БДО за работу с библиотечным фондом, за использование дезинф.средств при уборке туалетов работниками | Q16: Доплата в размере 20% от БДО за использование дезинфицирующих средств работниками | R16: Доплата в размере 25% от БДО за особые условия труда работников | S16: Итого доплаты | T16: Всего ФЗП за месяц | U16: ОПВ 10% | V16: ИПН | W16: ВОСМС | X16: Итого на руки | Y16: Всего ФЗП в год | Z16: Лечебно-оздоровительные пособия | AA16: Всего ФЗП с леч пособием | AB16: ОПВР 3.5% | AC16: Социальный налог 6% | AD16: Социальные отчисления 5% | AE16: ОСМС 3% | AF16: ВСЕГО ФОТ | AG16: Вид бюджета
A18: Административно-управленический персонал (АУП)
A19: 1 | B19: Директор | C19: Меирбек Меирлан Едигерулы | D19: 1 | E19: 1 | G19: 45146 | H19: 80 | I19: =H19*17697 -> 1415760 | J19: =I19*10% -> 141576 | S19: =SUM(J19:R19) -> 141576 | T19: =I19+S19 -> 1557336 | U19: =T19*10% -> 155733.6 | V19: =((T19-U19-W19)-(14*4325))*10% -> 130990.57 | W19: =T19*2% -> 31146.72 | X19: =T19-U19-V19-W19 -> 1239465.1 | Y19: =T19*12 -> 18688032 | Z19: =I19*2 -> 2831520 | AA19: =Y19+Z19 -> 21519552 | AB19: =AA19*3.5% -> 753184.32 | AC19: =(AA19*0.9-(W19*12))*11%-AD19 -> 1120942.1 | AD19: =AA19*0.9*5% -> 968379.84 | AE19: =AA19*3% -> 645586.56 | AF19: =AA19+AC19+AD19+AE19+AB19 -> 25007645 | AG19: РБ
A20: =A19+1 -> 2 | B20: Заместитель директора по учебной работе | C20: Кабулова Нурбану Таргиновна | D20: 2 | E20: 1 | G20: 43395 | H20: 32 | I20: =H20*17697 -> 566304 | J20: =I20*10% -> 56630.4 | S20: =SUM(J20:R20) -> 56630.4 | T20: =I20+S20 -> 622934.4 | U20: =T20*10% -> 62293.44 | V20: =((T20-U20-W20)-(14*4325))*10% -> 48763.227 | W20: =T20*2% -> 12458.688 | X20: =T20-U20-V20-W20 -> 499419.04 | Y20: =T20*12 -> 7475212.8 | Z20: =I20*2 -> 1132608 | AA20: =Y20+Z20 -> 8607820.8 | AB20: =AA20*3.5% -> 301273.73 | AC20: =(AA20*0.9-(W20*12))*11%-AD20 -> 448376.86 | AD20: =AA20*0.9*5% -> 387351.94 | AE20: =AA20*3% -> 258234.62 | AF20: =AA20+AC20+AD20+AE20+AB20 -> 10003058 | AG20: РБ
A21: =A20+1 -> 3 | B21: Заместитель директора по учебной работе | C21: Токтасбаев Бейбарыс Ералиевич | E21: 1 | G21: 44907 | H21: 30 | I21: =H21*17697 -> 530910 | J21: =I21*10% -> 53091 | S21: =SUM(J21:R21) -> 53091 | T21: =I21+S21 -> 584001 | U21: =T21*10% -> 58400.1 | V21: =((T21-U21-W21)-(14*4325))*10% -> 45337.088 | W21: =T21*2% -> 11680.02 | X21: =T21-U21-V21-W21 -> 468583.79 | Y21: =T21*12 -> 7008012 | Z21: =I21*2 -> 1061820 | AA21: =Y21+Z21 -> 8069832 | AB21: =AA21*3.5% -> 282444.12 | AC21: =(AA21*0.9-(W21*12))*11%-AD21 -> 420353.3 | AD21: =AA21*0.9*5% -> 363142.44 | AE21: =AA21*3% -> 242094.96 | AF21: =AA21+AC21+AD21+AE21+AB21 -> 9377866.8 | AG21: РБ
A22: =A21+1 -> 4 | B22: Заместитель директора по воспитательной работе | C22: Жасыбаева Лазат Карбозовна | D22: 2 | E22: 1 | G22: 44844 | H22: 30 | I22: =H22*17697 -> 530910 | J22: =I22*10% -> 53091 | S22: =SUM(J22:R22) -> 53091 | T22: =I22+S22 -> 584001 | U22: =T22*10% -> 58400.1 | V22: =((T22-U22-W22)-(14*4325))*10% -> 45337.088 | W22: =T22*2% -> 11680.02 | X22: =T22-U22-V22-W22 -> 468583.79 | Y22: =T22*12 -> 7008012 | Z22: =I22*2 -> 1061820 | AA22: =Y22+Z22 -> 8069832 | AB22: =AA22*3.5% -> 282444.12 | AC22: =(AA22*0.9-(W22*12))*11%-AD22 -> 420353.3 | AD22: =AA22*0.9*5% -> 363142.44 | AE22: =AA22*3% -> 242094.96 | AF22: =AA22+AC22+AD22+AE22+AB22 -> 9377866.8 | AG22: РБ
A23: =A22+1 -> 5 | B23: Заместитель директора по воспитательной работе | C23: Таукебаев Куаныш Муратбекович | E23: 1 | G23: 44805 | H23: 30 | I23: =H23*17697 -> 530910 | J23: =I23*10% -> 53091 | S23: =SUM(J23:R23) -> 53091 | T23: =I23+S23 -> 584001 | U23: =T23*10% -> 58400.1 | V23: =((T23-U23-W23)-(14*4325))*10% -> 45337.088 | W23: =T23*2% -> 11680.02 | X23: =T23-U23-V23-W23 -> 468583.79 | Y23: =T23*12 -> 7008012 | Z23: =I23*2 -> 1061820 | AA23: =Y23+Z23 -> 8069832 | AB23: =AA23*3.5% -> 282444.12 | AC23: =(AA23*0.9-(W23*12))*11%-AD23 -> 420353.3 | AD23: =AA23*0.9*5% -> 363142.44 | AE23: =AA23*3% -> 242094.96 | AF23: =AA23+AC23+AD23+AE23+AB23 -> 9377866.8 | AG23: РБ
A24: =A23+1 -> 6 | B24: Заместитель директора по профильно- экспериментальной работе | C24: Бегимбетов Талгат Полатович | D24: 1 | E24: 1 | G24: 45216 | H24: 30 | I24: =H24*17697 -> 530910 | J24: =I24*10% -> 53091 | S24: =SUM(J24:R24) -> 53091 | T24: =I24+S24 -> 584001 | U24: =T24*10% -> 58400.1 | V24: =((T24-U24-W24)-(14*4325))*10% -> 45337.088 | W24: =T24*2% -> 11680.02 | X24: =T24-U24-V24-W24 -> 468583.79 | Y24: =T24*12 -> 7008012 | Z24: =I24*2 -> 1061820 | AA24: =Y24+Z24 -> 8069832 | AB24: =AA24*3.5% -> 282444.12 | AC24: =(AA24*0.9-(W24*12))*11%-AD24 -> 420353.3 | AD24: =AA24*0.9*5% -> 363142.44 | AE24: =AA24*3% -> 242094.96 | AF24: =AA24+AC24+AD24+AE24+AB24 -> 9377866.8 | AG24: РБ
A25: =A24+1 -> 7 | B25: Заместитель директора по научно-методической работе | C25: Аубакирова Гульнур Габдувна | D25: 1 | E25: 1 | G25: 43355 | H25: 32 | I25: =H25*17697 -> 566304 | J25: =I25*10% -> 56630.4 | S25: =SUM(J25:R25) -> 56630.4 | T25: =I25+S25 -> 622934.4 | U25: =T25*10% -> 62293.44 | V25: =((T25-U25-W25)-(14*4325))*10% -> 48763.227 | W25: =T25*2% -> 12458.688 | X25: =T25-U25-V25-W25 -> 499419.04 | Y25: =T25*12 -> 7475212.8 | Z25: =I25*2 -> 1132608 | AA25: =Y25+Z25 -> 8607820.8 | AB25: =AA25*3.5% -> 301273.73 | AC25: =(AA25*0.9-(W25*12))*11%-AD25 -> 448376.86 | AD25: =AA25*0.9*5% -> 387351.94 | AE25: =AA25*3% -> 258234.62 | AF25: =AA25+AC25+AD25+AE25+AB25 -> 10003058 | AG25: РБ
B26: ИТОГО АУП пед работники | D26: =SUM(D19:D25) -> 7 | E26: =SUM(E19:E25) -> 7 | F26: =SUM(F19:F25) -> 0 | I26: =SUM(I19:I25) -> 4672008 | J26: =SUM(J19:J25) -> 467200.8 | K26: =SUM(K19:K25) -> 0 | L26: =SUM(L19:L25) -> 0 | M26: =SUM(M19:M25) -> 0 | N26: =SUM(N19:N25) -> 0 | O26: =SUM(O19:O25) -> 0 | P26: =SUM(P19:P25) -> 0 | ... AF26: =SUM(AF19:AF25) -> 82525228
A27: =A25+1 -> 8 | B27: Заместитель директора по административно-хозяйственной работе | C27: Алин Береке Адильханович | D27: 2 | E27: 1 | G27: 42263 | H27: 35 | I27: =H27*17697 -> 619395 | J27: =I27*10% -> 61939.5 | S27: =SUM(J27:R27) -> 61939.5 | T27: =I27+S27 -> 681334.5 | U27: =T27*10% -> 68133.45 | V27: =((T27-U27-W27)-(14*4325))*10% -> 53902.436 | W27: =T27*2% -> 13626.69 | X27: =T27-U27-V27-W27 -> 545671.92 | Y27: =T27*12 -> 8176014 | Z27: =I27*2 -> 1238790 | AA27: =Y27+Z27 -> 9414804 | AB27: =AA27*3.5% -> 329518.14 | AC27: =(AA27*0.9-(W27*12))*11%-AD27 -> 490412.19 | AD27: =AA27*0.9*5% -> 423666.18 | AE27: =AA27*3% -> 282444.12 | AF27: =AA27+AC27+AD27+AE27+AB27 -> 10940845 | AG27: РБ
A28: =A27+1 -> 9 | B28: Заведующий по хозяйственной работе | C28: Камбарбаев Айдын Майсаканович | E28: 1 | G28: 44106 | H28: 24 | I28: =H28*17697 -> 424728 | J28: =I28*10% -> 42472.8 | S28: =SUM(J28:R28) -> 42472.8 | T28: =I28+S28 -> 467200.8 | U28: =T28*10% -> 46720.08 | V28: =((T28-U28-W28)-(14*4325))*10% -> 35058.67 | W28: =T28*2% -> 9344.016 | X28: =T28-U28-V28-W28 -> 376078.03 | Y28: =T28*12 -> 5606409.6 | Z28: =I28*2 -> 849456 | AA28: =Y28+Z28 -> 6455865.6 | AB28: =AA28*3.5% -> 225955.3 | AC28: =(AA28*0.9-(W28*12))*11%-AD28 -> 336282.64 | AD28: =AA28*0.9*5% -> 290513.95 | AE28: =AA28*3% -> 193675.97 | AF28: =AA28+AC28+AD28+AE28+AB28 -> 7502293.5 | AG28: РБ
A29: =A28+1 -> 10 | B29: Экономист | C29: Куюкова Гаухар Ермековна | D29: 1 | E29: 1 | G29: 44853 | H29: 30 | I29: =H29*17697 -> 530910 | J29: =I29*10% -> 53091 | S29: =SUM(J29:R29) -> 53091 | T29: =I29+S29 -> 584001 | U29: =T29*10% -> 58400.1 | V29: =((T29-U29-W29)-(14*4325))*10% -> 45337.088 | W29: =T29*2% -> 11680.02 | X29: =T29-U29-V29-W29 -> 468583.79 | Y29: =T29*12 -> 7008012 | Z29: =I29*2 -> 1061820 | AA29: =Y29+Z29 -> 8069832 | AB29: =AA29*3.5% -> 282444.12 | AC29: =(AA29*0.9-(W29*12))*11%-AD29 -> 420353.3 | AD29: =AA29*0.9*5% -> 363142.44 | AE29: =AA29*3% -> 242094.96 | AF29: =AA29+AC29+AD29+AE29+AB29 -> 9377866.8 | AG29: РБ
A30: =A29+1 -> 11 | B30: Главный бухгалтер | C30: Абулова Жулдыз Муратовна | D30: 1 | E30: 1 | G30: 43710 | H30: 35 | I30: =H30*17697 -> 619395 | J30: =I30*10% -> 61939.5 | S30: =SUM(J30:R30) -> 61939.5 | T30: =I30+S30 -> 681334.5 | U30: =T30*10% -> 68133.45 | V30: =((T30-U30-W30)-(14*4325))*10% -> 53902.436 | W30: =T30*2% -> 13626.69 | X30: =T30-U30-V30-W30 -> 545671.92 | Y30: =T30*12 -> 8176014 | Z30: =I30*2 -> 1238790 | AA30: =Y30+Z30 -> 9414804 | AB30: =AA30*3.5% -> 329518.14 | AC30: =(AA30*0.9-(W30*12))*11%-AD30 -> 490412.19 | AD30: =AA30*0.9*5% -> 423666.18 | AE30: =AA30*3% -> 282444.12 | AF30: =AA30+AC30+AD30+AE30+AB30 -> 10940845 | AG30: РБ
A31: =A30+1 -> 12 | B31: Старший бухгалтер | C31: Қожамқұлова Жанна Пірмағанбетқызы | D31: 1 | E31: 1 | G31: 44105 | H31: 30 | I31: =H31*17697 -> 530910 | J31: =I31*10% -> 53091 | S31: =SUM(J31:R31) -> 53091 | T31: =I31+S31 -> 584001 | U31: =T31*10% -> 58400.1 | V31: =((T31-U31-W31)-(14*4325))*10% -> 45337.088 | W31: =T31*2% -> 11680.02 | X31: =T31-U31-V31-W31 -> 468583.79 | Y31: =T31*12 -> 7008012 | Z31: =I31*2 -> 1061820 | AA31: =Y31+Z31 -> 8069832 | AB31: =AA31*3.5% -> 282444.12 | AC31: =(AA31*0.9-(W31*12))*11%-AD31 -> 420353.3 | AD31: =AA31*0.9*5% -> 363142.44 | AE31: =AA31*3% -> 242094.96 | AF31: =AA31+AC31+AD31+AE31+AB31 -> 9377866.8 | AG31: РБ
A32: =A31+1 -> 13 | B32: Бухгалтер | C32: Сабирова Гулжан Саухановна | D32: 2 | E32: 1 | G32: 44939 | H32: 23 | I32: =H32*17697 -> 407031 | J32: =I32*10% -> 40703.1 | S32: =SUM(J32:R32) -> 40703.1 | T32: =I32+S32 -> 447734.1 | U32: =T32*10% -> 44773.41 | V32: =((T32-U32-W32)-(14*4325))*10% -> 33345.601 | W32: =T32*2% -> 8954.682 | X32: =T32-U32-V32-W32 -> 360660.41 | Y32: =T32*12 -> 5372809.2 | Z32: =I32*2 -> 814062 | AA32: =Y32+Z32 -> 6186871.2 | AB32: =AA32*3.5% -> 216540.49 | AC32: =(AA32*0.9-(W32*12))*11%-AD32 -> 322270.86 | AD32: =AA32*0.9*5% -> 278409.2 | AE32: =AA32*3% -> 185606.14 | AF32: =AA32+AC32+AD32+AE32+AB32 -> 7189697.9 | AG32: РБ
A33: =A32+1 -> 14 | B33: Бухгалтер | C33: Каныбетова Балжан Сериковна | E33: 1 | G33: 41860 | H33: 23 | I33: =H33*17697 -> 407031 | J33: =I33*10% -> 40703.1 | S33: =SUM(J33:R33) -> 40703.1 | T33: =I33+S33 -> 447734.1 | U33: =T33*10% -> 44773.41 | V33: =((T33-U33-W33)-(14*4325))*10% -> 33345.601 | W33: =T33*2% -> 8954.682 | X33: =T33-U33-V33-W33 -> 360660.41 | Y33: =T33*12 -> 5372809.2 | Z33: =I33*2 -> 814062 | AA33: =Y33+Z33 -> 6186871.2 | AB33: =AA33*3.5% -> 216540.49 | AC33: =(AA33*0.9-(W33*12))*11%-AD33 -> 322270.86 | AD33: =AA33*0.9*5% -> 278409.2 | AE33: =AA33*3% -> 185606.14 | AF33: =AA33+AC33+AD33+AE33+AB33 -> 7189697.9 | AG33: РБ
A34: =A33+1 -> 15 | B34: Специалист по закупкам | C34: Жанабилов Жандос Ерболатович | D34: 1 | E34: 1 | G34: 45019 | H34: 28 | I34: =H34*17697 -> 495516 | J34: =I34*10% -> 49551.6 | S34: =SUM(J34:R34) -> 49551.6 | T34: =I34+S34 -> 545067.6 | U34: =T34*10% -> 54506.76 | V34: =((T34-U34-W34)-(14*4325))*10% -> 41910.949 | W34: =T34*2% -> 10901.352 | X34: =T34-U34-V34-W34 -> 437748.54 | Y34: =T34*12 -> 6540811.2 | Z34: =I34*2 -> 991032 | AA34: =Y34+Z34 -> 7531843.2 | AB34: =AA34*3.5% -> 263614.51 | AC34: =(AA34*0.9-(W34*12))*11%-AD34 -> 392329.75 | AD34: =AA34*0.9*5% -> 338932.94 | AE34: =AA34*3% -> 225955.3 | AF34: =AA34+AC34+AD34+AE34+AB34 -> 8752675.7 | AG34: РБ
A35: =A34+1 -> 16 | B35: Юрист | C35: Токсеитова Гульмира Назымбековна | D35: 1 | E35: 1 | G35: 45232 | H35: 28 | I35: =H35*17697 -> 495516 | J35: =I35*10% -> 49551.6 | S35: =SUM(J35:R35) -> 49551.6 | T35: =I35+S35 -> 545067.6 | U35: =T35*10% -> 54506.76 | V35: =((T35-U35-W35)-(14*4325))*10% -> 41910.949 | W35: =T35*2% -> 10901.352 | X35: =T35-U35-V35-W35 -> 437748.54 | Y35: =T35*12 -> 6540811.2 | Z35: =I35*2 -> 991032 | AA35: =Y35+Z35 -> 7531843.2 | AB35: =AA35*3.5% -> 263614.51 | AC35: =(AA35*0.9-(W35*12))*11%-AD35 -> 392329.75 | AD35: =AA35*0.9*5% -> 338932.94 | AE35: =AA35*3% -> 225955.3 | AF35: =AA35+AC35+AD35+AE35+AB35 -> 8752675.7 | AG35: РБ
